Workbook

Sheet Base Ventas
A1: |
A4: Fecha Venta | B4: Mes | C4: No orden | D4: Concepto | E4: Cliente/Proveedor | F4: Codigo | G4: Descripcion del producto | H4: Cantidad | I4: Categoria | J4: Ciudad | K4: Lugar de entrega | L4: Status Despacho | M4: Transportadora | N4: No guia | O4: Fecha de despacho | P4: Fecha de Entrega | Q4: Status entrega | R4: Tiempo de despacho de orden | S4: Tiempo de entrega de la orden | T4: Cumple NNS | U4: Desvío NNS (Hábil) | V4: Reponsable Incumplimiento | W4: Valor despacho | X4: Diferencia valor real vs Estimado | Y4: Causal de Incumplimiento | Z4: Observaciones
A5: 46024 | B5: enero | C5: 100245 | D5: Venta | E5: German Toro | F5: TECUACO | G5: =IFERROR(VLOOKUP(F5,Productos!$A$2:$D$277,2,0)," ") -> Archivador TECU Caramelo | H5: 1 | I5: =IFERROR(VLOOKUP(F5,Productos!$A$2:$D$277,3,0)," ") -> Archivador | J5: Valle del Cauca | K5: Tuluá | L5: =IF(O5>0,"Despachado","En alistamiento") -> Despachado | M5: Envía | N5: 4000927-954101369750 | O5: 46035 | P5: 46036 | Q5: =IF(P5>0,"Entregado","En transito") -> Entregado | R5: =IF(L5="Despachado",NETWORKDAYS.INTL("05/01/2026",O5,11,Valores!$A$2:$A$19)-1,"PTE") -> 6 | S5: =IF(Q5="Entregado",NETWORKDAYS.INTL("05/01/2026",P5,11,Valores!$A$2:$A$19)-1,"PTE") -> 7 | T5: =IF(Q5="Entregado",IFERROR(IF(I5=VLOOKUP(I5,Valores!$K$1:$K$4,1,0),IF(S5<=VLOOKUP(I5,Valores!$K$1:$L$4,2,0),"Cumple","No cumple")),IF(S5<=VLOOKUP(K5,Valores!E:F,2,0),"Cumple","No cumple"))) -> No cumple | U5: =IFERROR(IF(T5="no cumple",S5-VLOOKUP(I5,Valores!$K$1:$L$4,2,0),0),S5-VLOOKUP(K5,Valores!E:F,2,0)) -> 2 | V5: Producción | W5: 71906 | Y5: Disponibilidad materia prima
A6: 46026 | B6: enero | C6: 100246 | D6: Venta | E6: Lizeth lopez | F6: TECUACO | G6: =IFERROR(VLOOKUP(F6,Productos!$A$2:$D$277,2,0)," ") -> Archivador TECU Caramelo | H6: 1 | I6: =IFERROR(VLOOKUP(F6,Productos!$A$2:$D$277,3,0)," ") -> Archivador | J6: Antioquia | K6: Sabaneta | L6: =IF(O6>0,"Despachado","En alistamiento") -> Despachado | M6: Envía | N6: 400089 -954101369783 | O6: 46035 | P6: 46036 | Q6: =IF(P6>0,"Entregado","En transito") -> Entregado | R6: =IF(L6="Despachado",NETWORKDAYS.INTL("05/01/2026",O6,11,Valores!$A$2:$A$19)-1,"PTE") -> 6 | S6: =IF(Q6="Entregado",NETWORKDAYS.INTL("05/01/2026",P6,11,Valores!$A$2:$A$19)-1,"PTE") -> 7 | T6: =IF(Q6="Entregado",IFERROR(IF(I6=VLOOKUP(I6,Valores!$K$1:$K$4,1,0),IF(S6<=VLOOKUP(I6,Valores!$K$1:$L$4,2,0),"Cumple","No cumple")),IF(S6<=VLOOKUP(K6,Valores!E:F,2,0),"Cumple","No cumple"))) -> No cumple | U6: =IFERROR(IF(T6="no cumple",S6-VLOOKUP(I6,Valores!$K$1:$L$4,2,0),0),S6-VLOOKUP(K6,Valores!E:F,2,0)) -> 2 | V6: Producción | W6: 68327 | Y6: Disponibilidad materia prima
A7: 46026 | B7: enero | C7: 100246 | D7: Venta | E7: Lizeth lopez | F7: TECUAFE | G7: =IFERROR(VLOOKUP(F7,Productos!$A$2:$D$277,2,0)," ") -> Archivador TECU Fresno Europeo | H7: 1 | I7: =IFERROR(VLOOKUP(F7,Productos!$A$2:$D$277,3,0)," ") -> Archivador | J7: Antioquia | K7: Sabaneta | L7: =IF(O7>0,"Despachado","En alistamiento") -> Despachado | M7: Envía | N7: 4000898-954101369742 | O7: 46035 | P7: 46036 | Q7: =IF(P7>0,"Entregado","En transito") -> Entregado | R7: =IF(L7="Despachado",NETWORKDAYS.INTL("05/01/2026",O7,11,Valores!$A$2:$A$19)-1,"PTE") -> 6 | S7: =IF(Q7="Entregado",NETWORKDAYS.INTL("05/01/2026",P7,11,Valores!$A$2:$A$19)-1,"PTE") -> 7 | T7: =IF(Q7="Entregado",IFERROR(IF(I7=VLOOKUP(I7,Valores!$K$1:$K$4,1,0),IF(S7<=VLOOKUP(I7,Valores!$K$1:$L$4,2,0),"Cumple","No cumple")),IF(S7<=VLOOKUP(K7,Valores!E:F,2,0),"Cumple","No cumple"))) -> No cumple | U7: =IFERROR(IF(T7="no cumple",S7-VLOOKUP(I7,Valores!$K$1:$L$4,2,0),0),S7-VLOOKUP(K7,Valores!E:F,2,0)) -> 2 | V7: Producción | W7: 68327 | Y7: Disponibilidad materia prima
A8: 46027 | B8: enero | C8: 100248 | D8: Venta | E8: Andres Naranjo | F8: TECUCT | G8: =IFERROR(VLOOKUP(F8,Productos!$A$2:$D$277,2,0)," ") -> Bandeja de cables | H8: 1 | I8: =IFERROR(VLOOKUP(F8,Productos!$A$2:$D$277,3,0)," ") -> Accesorio | J8: Cundinamarca | K8: Mosquera | L8: =IF(O8>0,"Despachado","En alistamiento") -> Despachado | M8: Coordinadora | N8: 3980164-84151477420 | O8: 46027 | P8: 46028 | Q8: =IF(P8>0,"Entregado","En transito") -> Entregado | R8: =IF(L8="Despachado",NETWORKDAYS.INTL(A8,O8,11,Valores!$A$2:$A$19)-1,"PTE") -> 0 | S8: =IF(Q8="Entregado",NETWORKDAYS.INTL(A8,P8,11,Valores!$A$2:$A$19)-1,"PTE") -> 1 | T8: =IF(Q8="Entregado",IFERROR(IF(I8=VLOOKUP(I8,Valores!$K$1:$K$4,1,0),IF(S8<=VLOOKUP(I8,Valores!$K$1:$L$4,2,0),"Cumple","No cumple")),IF(S8<=VLOOKUP(K8,Valores!E:F,2,0),"Cumple","No cumple"))) -> Cumple | U8: =IFERROR(IF(T8="no cumple",S8-VLOOKUP(I8,Valores!$K$1:$L$4,2,0),0),S8-VLOOKUP(K8,Valores!E:F,2,0)) -> 0 | W8: 26681
A9: 46027 | B9: enero | C9: 100249 | D9: Venta | E9: Adriana Urrea | F9: TECUTFE2C-60 | G9: =IFERROR(VLOOKUP(F9,Productos!$A$2:$D$277,2,0)," ") -> Superficie Escritorio Fresno Europeo 120x60 Clasico Small | H9: 1 | I9: =IFERROR(VLOOKUP(F9,Productos!$A$2:$D$277,3,0)," ") -> Superficie | J9: Antioquia | K9: Medellín | L9: =IF(O9>0,"Despachado","En alistamiento") -> Despachado | M9: Coordinadora | N9: 3987477-84151480114 | O9: 46029 | P9: 46030 | Q9: =IF(P9>0,"Entregado","En transito") -> Entregado | R9: =IF(L9="Despachado",NETWORKDAYS.INTL(A9,O9,11,Valores!$A$2:$A$19)-1,"PTE") -> 2 | S9: =IF(Q9="Entregado",NETWORKDAYS.INTL(A9,P9,11,Valores!$A$2:$A$19)-1,"PTE") -> 3 | T9: =IF(Q9="Entregado",IFERROR(IF(I9=VLOOKUP(I9,Valores!$K$1:$K$4,1,0),IF(S9<=VLOOKUP(I9,Valores!$K$1:$L$4,2,0),"Cumple","No cumple")),IF(S9<=VLOOKUP(K9,Valores!E:F,2,0),"Cumple","No cumple"))) -> Cumple | U9: =IFERROR(IF(T9="no cumple",S9-VLOOKUP(I9,Valores!$K$1:$L$4,2,0),0),S9-VLOOKUP(K9,Valores!E:F,2,0)) -> 0 | W9: 25952
A10: 46027 | B10: enero | C10: 100249 | D10: Venta | E10: Adriana Urrea | F10: TECU2FNG | G10: =IFERROR(VLOOKUP(F10,Productos!$A$2:$D$277,2,0)," ") -> Electric Standing Desk GO Negro | H10: 1 | I10: =IFERROR(VLOOKUP(F10,Productos!$A$2:$D$277,3,0)," ") -> Standing Desk | J10: Antioquia | K10: Medellín | L10: =IF(O10>0,"Despachado","En alistamiento") -> Despachado | M10: Coordinadora | N10: 3987474-84151480113 | O10: 46029 | P10: 46030 | Q10: =IF(P10>0,"Entregado","En transito") -> Entregado | R10: =IF(L10="Despachado",NETWORKDAYS.INTL(A10,O10,11,Valores!$A$2:$A$19)-1,"PTE") -> 2 | S10: =IF(Q10="Entregado",NETWORKDAYS.INTL(A10,P10,11,Valores!$A$2:$A$19)-1,"PTE") -> 3 | T10: =IF(Q10="Entregado",IFERROR(IF(I10=VLOOKUP(I10,Valores!$K$1:$K$4,1,0),IF(S10<=VLOOKUP(I10,Valores!$K$1:$L$4,2,0),"Cumple","No cumple")),IF(S10<=VLOOKUP(K10,Valores!E:F,2,0),"Cumple","No cumple"))) -> Cumple | U10: =IFERROR(IF(T10="no cumple",S10-VLOOKUP(I10,Valores!$K$1:$L$4,2,0),0),S10-VLOOKUP(K10,Valores!E:F,2,0)) -> 0 | W10: 43114
A11: 46027 | B11: enero | C11: 100250 | D11: Venta | E11: Duvan Sarmiento | F11: TECUTCO2C-60 | G11: =IFERROR(VLOOKUP(F11,Productos!$A$2:$D$277,2,0)," ") -> Superficie Escritorio Caramelo 120x60 Clasico Small | H11: 1 | I11: =IFERROR(VLOOKUP(F11,Productos!$A$2:$D$277,3,0)," ") -> Superficie | J11: Bogotá y alrededores | K11: Bogotá | L11: =IF(O11>0,"Despachado","En alistamiento") -> Despachado | M11: Coordinadora | N11: 3987838-84151480227 | O11: 46029 | P11: 46030 | Q11: =IF(P11>0,"Entregado","En transito") -> Entregado | R11: =IF(L11="Despachado",NETWORKDAYS.INTL(A11,O11,11,Valores!$A$2:$A$19)-1,"PTE") -> 2 | S11: =IF(Q11="Entregado",NETWORKDAYS.INTL(A11,P11,11,Valores!$A$2:$A$19)-1,"PTE") -> 3 | T11: =IF(Q11="Entregado",IFERROR(IF(I11=VLOOKUP(I11,Valores!$K$1:$K$4,1,0),IF(S11<=VLOOKUP(I11,Valores!$K$1:$L$4,2,0),"Cumple","No cumple")),IF(S11<=VLOOKUP(K11,Valores!E:F,2,0),"Cumple","No cumple"))) -> Cumple | U11: =IFERROR(IF(T11="no cumple",S11-VLOOKUP(I11,Valores!$K$1:$L$4,2,0),0),S11-VLOOKUP(K11,Valores!E:F,2,0)) -> 0 | W11: 25952
A12: 46027 | B12: enero | C12: 100250 | D12: Venta | E12: Duvan Sarmiento | F12: TECU3FBRO | G12: =IFERROR(VLOOKUP(F12,Productos!$A$2:$D$277,2,0)," ") -> Electric Standing Desk PRO Blanco | H12: 1 | I12: =IFERROR(VLOOKUP(F12,Productos!$A$2:$D$277,3,0)," ") -> Standing Desk | J12: Bogotá y alrededores | K12: Bogotá | L12: =IF(O12>0,"Despachado","En alistamiento") -> Despachado | M12: Coordinadora | N12: 3987834-84151480226 | O12: 46029 | P12: 46030 | Q12: =IF(P12>0,"Entregado","En transito") -> Entregado | R12: =IF(L12="Despachado",NETWORKDAYS.INTL(A12,O12,11,Valores!$A$2:$A$19)-1,"PTE") -> 2 | S12: =IF(Q12="Entregado",NETWORKDAYS.INTL(A12,P12,11,Valores!$A$2:$A$19)-1,"PTE") -> 3 | T12: =IF(Q12="Entregado",IFERROR(IF(I12=VLOOKUP(I12,Valores!$K$1:$K$4,1,0),IF(S12<=VLOOKUP(I12,Valores!$K$1:$L$4,2,0),"Cumple","No cumple")),IF(S12<=VLOOKUP(K12,Valores!E:F,2,0),"Cumple","No cumple"))) -> Cumple | U12: =IFERROR(IF(T12="no cumple",S12-VLOOKUP(I12,Valores!$K$1:$L$4,2,0),0),S12-VLOOKUP(K12,Valores!E:F,2,0)) -> 0 | W12: 43114
A13: 46027 | B13: enero | C13: 100250 | D13: Venta | E13: Duvan Sarmiento | F13: TECURECO-80 | G13: =IFERROR(VLOOKUP(F13,Productos!$A$2:$D$277,2,0)," ") -> Repisa Escritorio Caramelo x 80cm | H13: 1 | I13: =IFERROR(VLOOKUP(F13,Productos!$A$2:$D$277,3,0)," ") -> Repisa | J13: Bogotá y alrededores | K13: Bogotá | L13: =IF(O13>0,"Despachado","En alistamiento") -> Despachado | M13: Coordinadora | N13: 3987838-84151480227 | O13: 46029 | P13: 46030 | Q13: =IF(P13>0,"Entregado","En transito") -> Entregado | R13: =IF(L13="Despachado",NETWORKDAYS.INTL(A13,O13,11,Valores!$A$2:$A$19)-1,"PTE") -> 2 | S13: =IF(Q13="Entregado",NETWORKDAYS.INTL(A13,P13,11,Valores!$A$2:$A$19)-1,"PTE") -> 3 | T13: =IF(Q13="Entregado",IFERROR(IF(I13=VLOOKUP(I13,Valores!$K$1:$K$4,1,0),IF(S13<=VLOOKUP(I13,Valores!$K$1:$L$4,2,0),"Cumple","No cumple")),IF(S13<=VLOOKUP(K13,Valores!E:F,2,0),"Cumple","No cumple"))) -> Cumple | U13: =IFERROR(IF(T13="no cumple",S13-VLOOKUP(I13,Valores!$K$1:$L$4,2,0),0),S13-VLOOKUP(K13,Valores!E:F,2,0)) -> 0 | W13: 0
A14: 46028 | B14: enero | C14: 100251 | D14: Venta | E14: Andrés vasquez | F14: TECUTLC8x5-60 | G14: =IFERROR(VLOOKUP(F14,Productos!$A$2:$D$277,2,0)," ") -> Superficie en L Caramelo 180x150cm x60 | H14: 1 | I14: =IFERROR(VLOOKUP(F14,Productos!$A$2:$D$277,3,0)," ") -> Superficie | J14: Bogotá y alrededores | K14: Bogotá | L14: =IF(O14>0,"Despachado","En alistamiento") -> Despachado | M14: Envía | N14: 3987727-954101366327 | O14: 46029 | P14: 46030 | Q14: =IF(P14>0,"Entregado","En transito") -> Entregado | R14: =IF(L14="Despachado",NETWORKDAYS.INTL(A14,O14,11,Valores!$A$2:$A$19)-1,"PTE") -> 1 | S14: =IF(Q14="Entregado",NETWORKDAYS.INTL(A14,P14,11,Valores!$A$2:$A$19)-1,"PTE") -> 2 | T14: =IF(Q14="Entregado",IFERROR(IF(I14=VLOOKUP(I14,Valores!$K$1:$K$4,1,0),IF(S14<=VLOOKUP(I14,Valores!$K$1:$L$4,2,0),"Cumple","No cumple")),IF(S14<=VLOOKUP(K14,Valores!E:F,2,0),"Cumple","No cumple"))) -> Cumple | U14: =IFERROR(IF(T14="no cumple",S14-VLOOKUP(I14,Valores!$K$1:$L$4,2,0),0),S14-VLOOKUP(K14,Valores!E:F,2,0)) -> 0 | W14: 32487
A15: 46028 | B15: enero | C15: 100251 | D15: Venta | E15: Andrés vasquez | F15: TECULFN2 | G15: =IFERROR(VLOOKUP(F15,Productos!$A$2:$D$277,2,0)," ") -> Electric Standing Desk En L Frame Negro 2.0 | H15: 1 | I15: =IFERROR(VLOOKUP(F15,Productos!$A$2:$D$277,3,0)," ") -> Standing Desk | J15: Bogotá y alrededores | K15: Bogotá | L15: =IF(O15>0,"Despachado","En alistamiento") -> Despachado | M15: Coordinadora | N15: 3987490-84151480120 | O15: 46029 | P15: 46031 | Q15: =IF(P15>0,"Entregado","En transito") -> Entregado | R15: =IF(L15="Despachado",NETWORKDAYS.INTL(A15,O15,11,Valores!$A$2:$A$19)-1,"PTE") -> 1 | S15: =IF(Q15="Entregado",NETWORKDAYS.INTL(A15,P15,11,Valores!$A$2:$A$19)-1,"PTE") -> 3 | T15: =IF(Q15="Entregado",IFERROR(IF(I15=VLOOKUP(I15,Valores!$K$1:$K$4,1,0),IF(S15<=VLOOKUP(I15,Valores!$K$1:$L$4,2,0),"Cumple","No cumple")),IF(S15<=VLOOKUP(K15,Valores!E:F,2,0),"Cumple","No cumple"))) -> Cumple | U15: =IFERROR(IF(T15="no cumple",S15-VLOOKUP(I15,Valores!$K$1:$L$4,2,0),0),S15-VLOOKUP(K15,Valores!E:F,2,0)) -> 0 | W15: 65353
A16: 46028 | B16: enero | C16: 100251 | D16: Venta | E16: Andrés vasquez | G16: Servicio Instalación | H16: 1 | I16: Instalación | J16: Bogotá y alrededores | K16: Bogotá | L16: =IF(O16>0,"Despachado","En alistamiento") -> Despachado | M16: N/A | N16: N/A | O16: N/A | P16: N/A | Q16: =IF(P16>0,"Entregado","En transito") -> Entregado | R16: 0 | S16: 0 | T16: 0 | U16: =IFERROR(IF(T16="no cumple",S16-VLOOKUP(I16,Valores!$K$1:$L$4,2,0),0),S16-VLOOKUP(K16,Valores!E:F,2,0)) -> 0 | W16: 0
A17: 46028 | B17: enero | C17: 100252 | D17: Venta | E17: Luis Felipe Valencia Alvarez | F17: TECU2CURN-65 | G17: =IFERROR(VLOOKUP(F17,Productos!$A$2:$D$277,2,0)," ") -> Cajonero 2.0 Unicolor Roble Negro x65cm | H17: 1 | I17: =IFERROR(VLOOKUP(F17,Productos!$A$2:$D$277,3,0)," ") -> Archivador | J17: Quindío | K17: Armenia | L17: =IF(O17>0,"Despachado","En alistamiento") -> Despachado | M17: Particular | N17: N/A | O17: 46042 | P17: 46042 | Q17: =IF(P17>0,"Entregado","En transito") -> Entregado | R17: =IF(L17="Despachado",NETWORKDAYS.INTL(A17,O17,11,Valores!$A$2:$A$19)-1,"PTE") -> 11 | S17: =IF(Q17="Entregado",NETWORKDAYS.INTL(A17,P17,11,Valores!$A$2:$A$19)-1,"PTE") -> 11 | T17: =IF(Q17="Entregado",IFERROR(IF(I17=VLOOKUP(I17,Valores!$K$1:$K$4,1,0),IF(S17<=VLOOKUP(I17,Valores!$K$1:$L$4,2,0),"Cumple","No cumple")),IF(S17<=VLOOKUP(K17,Valores!E:F,2,0),"Cumple","No cumple"))) -> No cumple | U17: =IFERROR(IF(T17="no cumple",S17-VLOOKUP(I17,Valores!$K$1:$L$4,2,0),0),S17-VLOOKUP(K17,Valores!E:F,2,0)) -> 6 | V17: Producción | W17: 50000 | Y17: Disponibilidad materia prima
A18: 46029 | B18: enero | C18: 100256 | D18: Venta | E18: Luis Fernando Cruz Bermudez | F18: TECUTCO7C | G18: =IFERROR(VLOOKUP(F18,Productos!$A$2:$D$277,2,0)," ") -> Superficie Caramelo 170x70 Clasico | H18: 1 | I18: =IFERROR(VLOOKUP(F18,Productos!$A$2:$D$277,3,0)," ") -> Superficie | J18: Bogotá y alrededores | K18: Bogotá | L18: =IF(O18>0,"Despachado","En alistamiento") -> Despachado | M18: Envía | N18: 3990060-954101366844 | O18: 46030 | P18: 46031 | Q18: =IF(P18>0,"Entregado","En transito") -> Entregado | R18: =IF(L18="Despachado",NETWORKDAYS.INTL(A18,O18,11,Valores!$A$2:$A$19)-1,"PTE") -> 1 | S18: =IF(Q18="Entregado",NETWORKDAYS.INTL(A18,P18,11,Valores!$A$2:$A$19)-1,"PTE") -> 2 | T18: =IF(Q18="Entregado",IFERROR(IF(I18=VLOOKUP(I18,Valores!$K$1:$K$4,1,0),IF(S18<=VLOOKUP(I18,Valores!$K$1:$L$4,2,0),"Cumple","No cumple")),IF(S18<=VLOOKUP(K18,Valores!E:F,2,0),"Cumple","No cumple"))) -> Cumple | U18: =IFERROR(IF(T18="no cumple",S18-VLOOKUP(I18,Valores!$K$1:$L$4,2,0),0),S18-VLOOKUP(K18,Valores!E:F,2,0)) -> 0 | W18: 34253
A19: 46029 | B19: enero | C19: 100256 | D19: Venta | E19: Luis Fernando Cruz Bermudez | F19: TECU3FNPRO | G19: =IFERROR(VLOOKUP(F19,Productos!$A$2:$D$277,2,0)," ") -> Electric Standing Desk PRO Negro | H19: 1 | I19: =IFERROR(VLOOKUP(F19,Productos!$A$2:$D$277,3,0)," ") -> Standing Desk | J19: Bogotá y alrededores | K19: Bogotá | L19: =IF(O19>0,"Despachado","En alistamiento") -> Despachado | M19: Coordinadora | N19: 3989846-84151480984 | O19: 46030 | P19: 46032 | Q19: =IF(P19>0,"Entregado","En transito") -> Entregado | R19: =IF(L19="Despachado",NETWORKDAYS.INTL(A19,O19,11,Valores!$A$2:$A$19)-1,"PTE") -> 1 | S19: =IF(Q19="Entregado",NETWORKDAYS.INTL(A19,P19,11,Valores!$A$2:$A$19)-1,"PTE") -> 3 | T19: =IF(Q19="Entregado",IFERROR(IF(I19=VLOOKUP(I19,Valores!$K$1:$K$4,1,0),IF(S19<=VLOOKUP(I19,Valores!$K$1:$L$4,2,0),"Cumple","No cumple")),IF(S19<=VLOOKUP(K19,Valores!E:F,2,0),"Cumple","No cumple"))) -> Cumple | U19: =IFERROR(IF(T19="no cumple",S19-VLOOKUP(I19,Valores!$K$1:$L$4,2,0),0),S19-VLOOKUP(K19,Valores!E:F,2,0)) -> 0 | W19: 44550
A20: 46029 | B20: enero | C20: 100256 | D20: Venta | E20: Luis Fernando Cruz Bermudez | G20: Servicio Instalación | H20: 1 | I20: Instalación | J20: Bogotá y alrededores | K20: Bogotá | L20: =IF(O20>0,"Despachado","En alistamiento") -> Despachado | M20: N/A | N20: N/A | O20: N/A | P20: N/A | Q20: =IF(P20>0,"Entregado","En transito") -> Entregado | R20: 0 | S20: 0 | T20: 0 | U20: =IFERROR(IF(T20="no cumple",S20-VLOOKUP(I20,Valores!$K$1:$L$4,2,0),0),S20-VLOOKUP(K20,Valores!E:F,2,0)) -> 0 | W20: 0
A21: 46029 | B21: enero | C21: 100258 | D21: Venta | E21: Moba Code SAS | F21: TECUTLFE5X70 | G21: =IFERROR(VLOOKUP(F21,Productos!$A$2:$D$277,2,0)," ") -> Superficie Escritorio Fresno Europeo en L 150x70 | H21: 1 | I21: =IFERROR(VLOOKUP(F21,Productos!$A$2:$D$277,3,0)," ") -> Superficie | J21: Tolima | K21: Ibagué | L21: =IF(O21>0,"Despachado","En alistamiento") -> Despachado | M21: Envía | N21: 3990171-954101366854 | O21: 46030 | P21: 46031 | Q21: =IF(P21>0,"Entregado","En transito") -> Entregado | R21: =IF(L21="Despachado",NETWORKDAYS.INTL(A21,O21,11,Valores!$A$2:$A$19)-1,"PTE") -> 1 | S21: =IF(Q21="Entregado",NETWORKDAYS.INTL(A21,P21,11,Valores!$A$2:$A$19)-1,"PTE") -> 2 | T21: =IF(Q21="Entregado",IFERROR(IF(I21=VLOOKUP(I21,Valores!$K$1:$K$4,1,0),IF(S21<=VLOOKUP(I21,Valores!$K$1:$L$4,2,0),"Cumple","No cumple")),IF(S21<=VLOOKUP(K21,Valores!E:F,2,0),"Cumple","No cumple"))) -> Cumple | U21: =IFERROR(IF(T21="no cumple",S21-VLOOKUP(I21,Valores!$K$1:$L$4,2,0),0),S21-VLOOKUP(K21,Valores!E:F,2,0)) -> 0 | W21: 40366
A22: 46029 | B22: enero | C22: 100258 | D22: Venta | E22: Moba Code SAS | F22: TECULFN2 | G22: =IFERROR(VLOOKUP(F22,Productos!$A$2:$D$277,2,0)," ") -> Electric Standing Desk En L Frame Negro 2.0 | H22: 1 | I22: =IFERROR(VLOOKUP(F22,Productos!$A$2:$D$277,3,0)," ") -> Standing Desk | J22: Tolima | K22: Ibagué | L22: =IF(O22>0,"Despachado","En alistamiento") -> Despachado | M22: Coordinadora | N22: 3989863-84151480993 | O22: 46030 | P22: 46031 | Q22: =IF(P22>0,"Entregado","En transito") -> Entregado | R22: =IF(L22="Despachado",NETWORKDAYS.INTL(A22,O22,11,Valores!$A$2:$A$19)-1,"PTE") -> 1 | S22: =IF(Q22="Entregado",NETWORKDAYS.INTL(A22,P22,11,Valores!$A$2:$A$19)-1,"PTE") -> 2 | T22: =IF(Q22="Entregado",IFERROR(IF(I22=VLOOKUP(I22,Valores!$K$1:$K$4,1,0),IF(S22<=VLOOKUP(I22,Valores!$K$1:$L$4,2,0),"Cumple","No cumple")),IF(S22<=VLOOKUP(K22,Valores!E:F,2,0),"Cumple","No cumple"))) -> Cumple | U22: =IFERROR(IF(T22="no cumple",S22-VLOOKUP(I22,Valores!$K$1:$L$4,2,0),0),S22-VLOOKUP(K22,Valores!E:F,2,0)) -> 0 | W22: 65353
A23: 46029 | B23: enero | C23: 100258 | D23: Venta | E23: Moba Code SAS | F23: TECUREFE -47 | G23: =IFERROR(VLOOKUP(F23,Productos!$A$2:$D$277,2,0)," ") -> Repisa Escritorio Fresno Europeo x 47cm | H23: 2 | I23: =IFERROR(VLOOKUP(F23,Productos!$A$2:$D$277,3,0)," ") -> Repisa | J23: Tolima | K23: Ibagué | L23: =IF(O23>0,"Despachado","En alistamiento") -> Despachado | M23: Coordinadora | N23: 3990171-954101366854 | O23: 46030 | P23: 46031 | Q23: =IF(P23>0,"Entregado","En transito") -> Entregado | R23: =IF(L23="Despachado",NETWORKDAYS.INTL(A23,O23,11,Valores!$A$2:$A$19)-1,"PTE") -> 1 | S23: =IF(Q23="Entregado",NETWORKDAYS.INTL(A23,P23,11,Valores!$A$2:$A$19)-1,"PTE") -> 2 | T23: =IF(Q23="Entregado",IFERROR(IF(I23=VLOOKUP(I23,Valores!$K$1:$K$4,1,0),IF(S23<=VLOOKUP(I23,Valores!$K$1:$L$4,2,0),"Cumple","No cumple")),IF(S23<=VLOOKUP(K23,Valores!E:F,2,0),"Cumple","No cumple"))) -> Cumple | U23: =IFERROR(IF(T23="no cumple",S23-VLOOKUP(I23,Valores!$K$1:$L$4,2,0),0),S23-VLOOKUP(K23,Valores!E:F,2,0)) -> 0 | W23: 0
A24: 46029 | B24: enero | C24: 100258 | D24: Venta | E24: Moba Code SAS | F24: TECUBLS | G24: =IFERROR(VLOOKUP(F24,Productos!$A$2:$D$277,2,0)," ") -> Laptop Stand B | H24: 2 | I24: =IFERROR(VLOOKUP(F24,Productos!$A$2:$D$277,3,0)," ") -> Accesorio | J24: Tolima | K24: Ibagué | L24: =IF(O24>0,"Despachado","En alistamiento") -> Despachado | M24: Coordinadora | N24: 3989874-84151480998 | O24: 46030 | P24: 46031 | Q24: =IF(P24>0,"Entregado","En transito") -> Entregado | R24: =IF(L24="Despachado",NETWORKDAYS.INTL(A24,O24,11,Valores!$A$2:$A$19)-1,"PTE") -> 1 | S24: =IF(Q24="Entregado",NETWORKDAYS.INTL(A24,P24,11,Valores!$A$2:$A$19)-1,"PTE") -> 2 | T24: =IF(Q24="Entregado",IFERROR(IF(I24=VLOOKUP(I24,Valores!$K$1:$K$4,1,0),IF(S24<=VLOOKUP(I24,Valores!$K$1:$L$4,2,0),"Cumple","No cumple")),IF(S24<=VLOOKUP(K24,Valores!E:F,2,0),"Cumple","No cumple"))) -> Cumple | U24: =IFERROR(IF(T24="no cumple",S24-VLOOKUP(I24,Valores!$K$1:$L$4,2,0),0),S24-VLOOKUP(K24,Valores!E:F,2,0)) -> 0 | W24: 0
A25: 46029 | B25: enero | C25: 100258 | D25: Venta | E25: Moba Code SAS | F25: TECUBDPA | G25: =IFERROR(VLOOKUP(F25,Productos!$A$2:$D$277,2,0)," ") -> Desk Pad B Negro Azul | H25: 2 | I25: =IFERROR(VLOOKUP(F25,Productos!$A$2:$D$277,3,0)," ") -> Accesorio | J25: Tolima | K25: Ibagué | L25: =IF(O25>0,"Despachado","En alistamiento") -> Despachado | M25: Coordinadora | N25: 3989874-84151480998 | O25: 46030 | P25: 46031 | Q25: =IF(P25>0,"Entregado","En transito") -> Entregado | R25: =IF(L25="Despachado",NETWORKDAYS.INTL(A25,O25,11,Valores!$A$2:$A$19)-1,"PTE") -> 1 | S25: =IF(Q25="Entregado",NETWORKDAYS.INTL(A25,P25,11,Valores!$A$2:$A$19)-1,"PTE") -> 2 | T25: =IF(Q25="Entregado",IFERROR(IF(I25=VLOOKUP(I25,Valores!$K$1:$K$4,1,0),IF(S25<=VLOOKUP(I25,Valores!$K$1:$L$4,2,0),"Cumple","No cumple")),IF(S25<=VLOOKUP(K25,Valores!E:F,2,0),"Cumple","No cumple"))) -> Cumple | U25: =IFERROR(IF(T25="no cumple",S25-VLOOKUP(I25,Valores!$K$1:$L$4,2,0),0),S25-VLOOKUP(K25,Valores!E:F,2,0)) -> 0 | W25: 17787
A26: 46029 | B26: enero | C26: 100258 | D26: Venta | E26: Moba Code SAS | F26: TECUCT | G26: =IFERROR(VLOOKUP(F26,Productos!$A$2:$D$277,2,0)," ") -> Bandeja de cables | H26: 1 | I26: =IFERROR(VLOOKUP(F26,Productos!$A$2:$D$277,3,0)," ") -> Accesorio | J26: Tolima | K26: Ibagué | L26: =IF(O26>0,"Despachado","En alistamiento") -> Despachado | M26: Coordinadora | N26: 3989884-84151481002 | O26: 46030 | P26: 46031 | Q26: =IF(P26>0,"Entregado","En transito") -> Entregado | R26: =IF(L26="Despachado",NETWORKDAYS.INTL(A26,O26,11,Valores!$A$2:$A$19)-1,"PTE") -> 1 | S26: =IF(Q26="Entregado",NETWORKDAYS.INTL(A26,P26,11,Valores!$A$2:$A$19)-1,"PTE") -> 2 | T26: =IF(Q26="Entregado",IFERROR(IF(I26=VLOOKUP(I26,Valores!$K$1:$K$4,1,0),IF(S26<=VLOOKUP(I26,Valores!$K$1:$L$4,2,0),"Cumple","No cumple")),IF(S26<=VLOOKUP(K26,Valores!E:F,2,0),"Cumple","No cumple"))) -> Cumple | U26: =IFERROR(IF(T26="no cumple",S26-VLOOKUP(I26,Valores!$K$1:$L$4,2,0),0),S26-VLOOKUP(K26,Valores!E:F,2,0)) -> 0 | W26: 26681
A27: 46029 | B27: enero | C27: 100258 | D27: Venta | E27: Moba Code SAS | F27: TECUDSG | G27: =IFERROR(VLOOKUP(F27,Productos!$A$2:$D$277,2,0)," ") -> Desk Stool Gris Silla ajustable | H27: 1 | I27: =IFERROR(VLOOKUP(F27,Productos!$A$2:$D$277,3,0)," ") -> Silla | J27: Tolima | K27: Ibagué | L27: =IF(O27>0,"Despachado","En alistamiento") -> Despachado | M27: Coordinadora | N27: 3989900-84151481009 | O27: 46030 | P27: 46031 | Q27: =IF(P27>0,"Entregado","En transito") -> Entregado | R27: =IF(L27="Despachado",NETWORKDAYS.INTL(A27,O27,11,Valores!$A$2:$A$19)-1,"PTE") -> 1 | S27: =IF(Q27="Entregado",NETWORKDAYS.INTL(A27,P27,11,Valores!$A$2:$A$19)-1,"PTE") -> 2 | T27: =IF(Q27="Entregado",IFERROR(IF(I27=VLOOKUP(I27,Valores!$K$1:$K$4,1,0),IF(S27<=VLOOKUP(I27,Valores!$K$1:$L$4,2,0),"Cumple","No cumple")),IF(S27<=VLOOKUP(K27,Valores!E:F,2,0),"Cumple","No cumple"))) -> Cumple | U27: =IFERROR(IF(T27="no cumple",S27-VLOOKUP(I27,Valores!$K$1:$L$4,2,0),0),S27-VLOOKUP(K27,Valores!E:F,2,0)) -> 0 | W27: 27803
A28: 46030 | B28: enero | C28: 100260 | D28: Venta | E28: Jessner Mejía | F28: TECUTFE2C-60 | G28: =IFERROR(VLOOKUP(F28,Productos!$A$2:$D$277,2,0)," ") -> Superficie Escritorio Fresno Europeo 120x60 Clasico Small | H28: 1 | I28: =IFERROR(VLOOKUP(F28,Productos!$A$2:$D$277,3,0)," ") -> Superficie | J28: Cauca | K28: Popayán | L28: =IF(O28>0,"Despachado","En alistamiento") -> Despachado | M28: Coordinadora | N28: 3989921-84151481020 | O28: 46030 | P28: 46032 | Q28: =IF(P28>0,"Entregado","En transito") -> Entregado | R28: =IF(L28="Despachado",NETWORKDAYS.INTL(A28,O28,11,Valores!$A$2:$A$19)-1,"PTE") -> 0 | S28: =IF(Q28="Entregado",NETWORKDAYS.INTL(A28,P28,11,Valores!$A$2:$A$19)-1,"PTE") -> 2 | T28: =IF(Q28="Entregado",IFERROR(IF(I28=VLOOKUP(I28,Valores!$K$1:$K$4,1,0),IF(S28<=VLOOKUP(I28,Valores!$K$1:$L$4,2,0),"Cumple","No cumple")),IF(S28<=VLOOKUP(K28,Valores!E:F,2,0),"Cumple","No cumple"))) -> Cumple | U28: =IFERROR(IF(T28="no cumple",S28-VLOOKUP(I28,Valores!$K$1:$L$4,2,0),0),S28-VLOOKUP(K28,Valores!E:F,2,0)) -> 0 | W28: 29698
A29: 46030 | B29: enero | C29: 100260 | D29: Venta | E29: Jessner Mejía | F29: TECU3FBRO | G29: =IFERROR(VLOOKUP(F29,Productos!$A$2:$D$277,2,0)," ") -> Electric Standing Desk PRO Blanco | H29: 1 | I29: =IFERROR(VLOOKUP(F29,Productos!$A$2:$D$277,3,0)," ") -> Standing Desk | J29: Cauca | K29: Popayán | L29: =IF(O29>0,"Despachado","En alistamiento") -> Despachado | M29: Coordinadora | N29: 3989918-84151481019 | O29: 46030 | P29: 46032 | Q29: =IF(P29>0,"Entregado","En transito") -> Entregado | R29: =IF(L29="Despachado",NETWORKDAYS.INTL(A29,O29,11,Valores!$A$2:$A$19)-1,"PTE") -> 0 | S29: =IF(Q29="Entregado",NETWORKDAYS.INTL(A29,P29,11,Valores!$A$2:$A$19)-1,"PTE") -> 2 | T29: =IF(Q29="Entregado",IFERROR(IF(I29=VLOOKUP(I29,Valores!$K$1:$K$4,1,0),IF(S29<=VLOOKUP(I29,Valores!$K$1:$L$4,2,0),"Cumple","No cumple")),IF(S29<=VLOOKUP(K29,Valores!E:F,2,0),"Cumple","No cumple"))) -> Cumple | U29: =IFERROR(IF(T29="no cumple",S29-VLOOKUP(I29,Valores!$K$1:$L$4,2,0),0),S29-VLOOKUP(K29,Valores!E:F,2,0)) -> 0 | W29: 47674
A30: 46037 | B30: enero | C30: 100260 | D30: Novedad | E30: Jessner Mejía | F30: TECUTFE2C-60 | G30: =IFERROR(VLOOKUP(F30,Productos!$A$2:$D$277,2,0)," ") -> Superficie Escritorio Fresno Europeo 120x60 Clasico Small | H30: 1 | I30: =IFERROR(VLOOKUP(F30,Productos!$A$2:$D$277,3,0)," ") -> Superficie | J30: Cauca | K30: Popayán | L30: =IF(O30>0,"Despachado","En alistamiento") -> Despachado | M30: Coordinadora | N30: 4010063-84151488641 | O30: 46038 | P30: 46039 | Q30: =IF(P30>0,"Entregado","En transito") -> Entregado | R30: =IF(L30="Despachado",NETWORKDAYS.INTL(A30,O30,11,Valores!$A$2:$A$19)-1,"PTE") -> 1 | S30: =IF(Q30="Entregado",NETWORKDAYS.INTL(A30,P30,11,Valores!$A$2:$A$19)-1,"PTE") -> 2 | T30: =IF(Q30="Entregado",IFERROR(IF(I30=VLOOKUP(I30,Valores!$K$1:$K$4,1,0),IF(S30<=VLOOKUP(I30,Valores!$K$1:$L$4,2,0),"Cumple","No cumple")),IF(S30<=VLOOKUP(K30,Valores!E:F,2,0),"Cumple","No cumple"))) -> Cumple | U30: =IFERROR(IF(T30="no cumple",S30-VLOOKUP(I30,Valores!$K$1:$L$4,2,0),0),S30-VLOOKUP(K30,Valores!E:F,2,0)) -> 0 | V30: Producción | W30: 33316 | Z30: Se realizó envío nueva superficie, porque se hicieron las tuercas de inserto en espacios diferente y no se podía atornillar la bandeja.
A31: 46030 | B31: enero | C31: 100261 | D31: Venta | E31: Nicolas Simmonds | F31: TECU2CBC-73 | G31: =IFERROR(VLOOKUP(F31,Productos!$A$2:$D$277,2,0)," ") -> Cajonero 2.0 Bicolor Caramelo x73cm | H31: 1 | I31: =IFERROR(VLOOKUP(F31,Productos!$A$2:$D$277,3,0)," ") -> Archivador | J31: Bogotá y alrededores | K31: Bogotá | L31: =IF(O31>0,"Despachado","En alistamiento") -> Despachado | M31: Envía | N31: 4026700-954101377299 | O31: 46044 | P31: 46045 | Q31: =IF(P31>0,"Entregado","En transito") -> Entregado | R31: =IF(L31="Despachado",NETWORKDAYS.INTL(A31,O31,11,Valores!$A$2:$A$19)-1,"PTE") -> 11 | S31: =IF(Q31="Entregado",NETWORKDAYS.INTL(A31,P31,11,Valores!$A$2:$A$19)-1,"PTE") -> 12 | T31: =IF(Q31="Entregado",IFERROR(IF(I31=VLOOKUP(I31,Valores!$K$1:$K$4,1,0),IF(S31<=VLOOKUP(I31,Valores!$K$1:$L$4,2,0),"Cumple","No cumple")),IF(S31<=VLOOKUP(K31,Valores!E:F,2,0),"Cumple","No cumple"))) -> No cumple | U31: =IFERROR(IF(T31="no cumple",S31-VLOOKUP(I31,Valores!$K$1:$L$4,2,0),0),S31-VLOOKUP(K31,Valores!E:F,2,0)) -> 7 | V31: Producción | W31: 57135 | Y31: Disponibilidad materia prima
A32: 46034 | B32: enero | C32: 100264 | D32: Venta | E32: Alison Ruiz | F32: TECUTB2C-60 | G32: =IFERROR(VLOOKUP(F32,Productos!$A$2:$D$277,2,0)," ") -> Superficie Escritorio Blanco (Niebla) 120x60 Clasico Small | H32: 1 | I32: =IFERROR(VLOOKUP(F32,Productos!$A$2:$D$277,3,0)," ") -> Superficie | J32: Bogotá y alrededores | K32: Bogotá | L32: =IF(O32>0,"Despachado","En alistamiento") -> Despachado | M32: Coordinadora | N32: 4003463-84151486019 | O32: 46037 | P32: 46038 | Q32: =IF(P32>0,"Entregado","En transito") -> Entregado | R32: =IF(L32="Despachado",NETWORKDAYS.INTL(A32,O32,11,Valores!$A$2:$A$19)-1,"PTE") -> 2 | S32: =IF(Q32="Entregado",NETWORKDAYS.INTL(A32,P32,11,Valores!$A$2:$A$19)-1,"PTE") -> 3 | T32: =IF(Q32="Entregado",IFERROR(IF(I32=VLOOKUP(I32,Valores!$K$1:$K$4,1,0),IF(S32<=VLOOKUP(I32,Valores!$K$1:$L$4,2,0),"Cumple","No cumple")),IF(S32<=VLOOKUP(K32,Valores!E:F,2,0),"Cumple","No cumple"))) -> Cumple | U32: =IFERROR(IF(T32="no cumple",S32-VLOOKUP(I32,Valores!$K$1:$L$4,2,0),0),S32-VLOOKUP(K32,Valores!E:F,2,0)) -> 0 | W32: 25952
A33: 46034 | B33: enero | C33: 100264 | D33: Venta | E33: Alison Ruiz | F33: TECU2FNG | G33: =IFERROR(VLOOKUP(F33,Productos!$A$2:$D$277,2,0)," ") -> Electric Standing Desk GO Negro | H33: 1 | I33: =IFERROR(VLOOKUP(F33,Productos!$A$2:$D$277,3,0)," ") -> Standing Desk | J33: Bogotá y alrededores | K33: Bogotá | L33: =IF(O33>0,"Despachado","En alistamiento") -> Despachado | M33: Coordinadora | N33: 4003461-84151486011 | O33: 46037 | P33: 46038 | Q33: =IF(P33>0,"Entregado","En transito") -> Entregado | R33: =IF(L33="Despachado",NETWORKDAYS.INTL(A33,O33,11,Valores!$A$2:$A$19)-1,"PTE") -> 2 | S33: =IF(Q33="Entregado",NETWORKDAYS.INTL(A33,P33,11,Valores!$A$2:$A$19)-1,"PTE") -> 3 | T33: =IF(Q33="Entregado",IFERROR(IF(I33=VLOOKUP(I33,Valores!$K$1:$K$4,1,0),IF(S33<=VLOOKUP(I33,Valores!$K$1:$L$4,2,0),"Cumple","No cumple")),IF(S33<=VLOOKUP(K33,Valores!E:F,2,0),"Cumple","No cumple"))) -> Cumple | U33: =IFERROR(IF(T33="no cumple",S33-VLOOKUP(I33,Valores!$K$1:$L$4,2,0),0),S33-VLOOKUP(K33,Valores!E:F,2,0)) -> 0 | W33: 43114
A34: 46035 | B34: enero | C34: 100265 | D34: Venta | E34: Jonathan Enrique Pacheco Jimenez | F34: TECURECO-110 | G34: =IFERROR(VLOOKUP(F34,Productos!$A$2:$D$277,2,0)," ") -> Repisa Escritorio Caramelo x 110cm | H34: 1 | I34: =IFERROR(VLOOKUP(F34,Productos!$A$2:$D$277,3,0)," ") -> Repisa | J34: Bolívar | K34: Cartagena | L34: =IF(O34>0,"Despachado","En alistamiento") -> Despachado | M34: Coordinadora | N34: 4003635-84151486070 | O34: 46037 | P34: 46039 | Q34: =IF(P34>0,"Entregado","En transito") -> Entregado | R34: =IF(L34="Despachado",NETWORKDAYS.INTL(A34,O34,11,Valores!$A$2:$A$19)-1,"PTE") -> 2 | S34: =IF(Q34="Entregado",NETWORKDAYS.INTL(A34,P34,11,Valores!$A$2:$A$19)-1,"PTE") -> 4 | T34: =IF(Q34="Entregado",IFERROR(IF(I34=VLOOKUP(I34,Valores!$K$1:$K$4,1,0),IF(S34<=VLOOKUP(I34,Valores!$K$1:$L$4,2,0),"Cumple","No cumple")),IF(S34<=VLOOKUP(K34,Valores!E:F,2,0),"Cumple","No cumple"))) -> Cumple | U34: =IFERROR(IF(T34="no cumple",S34-VLOOKUP(I34,Valores!$K$1:$L$4,2,0),0),S34-VLOOKUP(K34,Valores!E:F,2,0)) -> 0 | W34: 40669
A35: 46035 | B35: enero | C35: 100266 | D35: Venta | E35: Adriana Chavarro | F35: TECUTFE6C-80 | G35: =IFERROR(VLOOKUP(F35,Productos!$A$2:$D$277,2,0)," ") -> Superficie Escritorio Fresno Europeo 160x80 Clasico | H35: 1 | I35: =IFERROR(VLOOKUP(F35,Productos!$A$2:$D$277,3,0)," ") -> Superficie | J35: Bogotá y alrededores | K35: Bogotá | L35: =IF(O35>0,"Despachado","En alistamiento") -> Despachado | M35: Envía | N35: 4006959-954101371581 | O35: 46037 | P35: 46038 | Q35: =IF(P35>0,"Entregado","En transito") -> Entregado | R35: =IF(L35="Despachado",NETWORKDAYS.INTL(A35,O35,11,Valores!$A$2:$A$19)-1,"PTE") -> 2 | S35: =IF(Q35="Entregado",NETWORKDAYS.INTL(A35,P35,11,Valores!$A$2:$A$19)-1,"PTE") -> 3 | T35: =IF(Q35="Entregado",IFERROR(IF(I35=VLOOKUP(I35,Valores!$K$1:$K$4,1,0),IF(S35<=VLOOKUP(I35,Valores!$K$1:$L$4,2,0),"Cumple","No cumple")),IF(S35<=VLOOKUP(K35,Valores!E:F,2,0),"Cumple","No cumple"))) -> Cumple | U35: =IFERROR(IF(T35="no cumple",S35-VLOOKUP(I35,Valores!$K$1:$L$4,2,0),0),S35-VLOOKUP(K35,Valores!E:F,2,0)) -> 0 | W35: 34487
A36: 46035 | B36: enero | C36: 100266 | D36: Venta | E36: Adriana Chavarro | F36: TECU3FBRO | G36: =IFERROR(VLOOKUP(F36,Productos!$A$2:$D$277,2,0)," ") -> Electric Standing Desk PRO Blanco | H36: 1 | I36: =IFERROR(VLOOKUP(F36,Productos!$A$2:$D$277,3,0)," ") -> Standing Desk | J36: Bogotá y alrededores | K36: Bogotá | L36: =IF(O36>0,"Despachado","En alistamiento") -> Despachado | M36: Coordinadora | N36: 4006929-84151487326 | O36: 46037 | P36: 46038 | Q36: =IF(P36>0,"Entregado","En transito") -> Entregado | R36: =IF(L36="Despachado",NETWORKDAYS.INTL(A36,O36,11,Valores!$A$2:$A$19)-1,"PTE") -> 2 | S36: =IF(Q36="Entregado",NETWORKDAYS.INTL(A36,P36,11,Valores!$A$2:$A$19)-1,"PTE") -> 3 | T36: =IF(Q36="Entregado",IFERROR(IF(I36=VLOOKUP(I36,Valores!$K$1:$K$4,1,0),IF(S36<=VLOOKUP(I36,Valores!$K$1:$L$4,2,0),"Cumple","No cumple")),IF(S36<=VLOOKUP(K36,Valores!E:F,2,0),"Cumple","No cumple"))) -> Cumple | U36: =IFERROR(IF(T36="no cumple",S36-VLOOKUP(I36,Valores!$K$1:$L$4,2,0),0),S36-VLOOKUP(K36,Valores!E:F,2,0)) -> 0 | W36: 44550
A37: 46036 | B37: enero | C37: 100267 | D37: Venta | E37: EFRALU SAS / DANIEL GARCIA | F37: TECUTLCCS | G37: =IFERROR(VLOOKUP(F37,Productos!$A$2:$D$277,2,0)," ") -> Superficie en L Caramelo 180x150cm x 70 | H37: 1 | I37: =IFERROR(VLOOKUP(F37,Productos!$A$2:$D$277,3,0)," ") -> Superficie | J37: Bogotá y alrededores | K37: Bogotá | L37: =IF(O37>0,"Despachado","En alistamiento") -> Despachado | M37: Envía | N37: 4010031-954101372531 | O37: 46038 | P37: 46039 | Q37: =IF(P37>0,"Entregado","En transito") -> Entregado | R37: =IF(L37="Despachado",NETWORKDAYS.INTL(A37,O37,11,Valores!$A$2:$A$19)-1,"PTE") -> 2 | S37: =IF(Q37="Entregado",NETWORKDAYS.INTL(A37,P37,11,Valores!$A$2:$A$19)-1,"PTE") -> 3 | T37: =IF(Q37="Entregado",IFERROR(IF(I37=VLOOKUP(I37,Valores!$K$1:$K$4,1,0),IF(S37<=VLOOKUP(I37,Valores!$K$1:$L$4,2,0),"Cumple","No cumple")),IF(S37<=VLOOKUP(K37,Valores!E:F,2,0),"Cumple","No cumple"))) -> Cumple | U37: =IFERROR(IF(T37="no cumple",S37-VLOOKUP(I37,Valores!$K$1:$L$4,2,0),0),S37-VLOOKUP(K37,Valores!E:F,2,0)) -> 0 | W37: 36093
A38: 46036 | B38: enero | C38: 100267 | D38: Venta | E38: EFRALU SAS / DANIEL GARCIA | F38: TECULFN2 | G38: =IFERROR(VLOOKUP(F38,Productos!$A$2:$D$277,2,0)," ") -> Electric Standing Desk En L Frame Negro 2.0 | H38: 1 | I38: =IFERROR(VLOOKUP(F38,Productos!$A$2:$D$277,3,0)," ") -> Standing Desk | J38: Bogotá y alrededores | K38: Bogotá | L38: =IF(O38>0,"Despachado","En alistamiento") -> Despachado | M38: Coordinadora | N38: 4009949-84151488583 | O38: 46038 | P38: 46041 | Q38: =IF(P38>0,"Entregado","En transito") -> Entregado | R38: =IF(L38="Despachado",NETWORKDAYS.INTL(A38,O38,11,Valores!$A$2:$A$19)-1,"PTE") -> 2 | S38: =IF(Q38="Entregado",NETWORKDAYS.INTL(A38,P38,11,Valores!$A$2:$A$19)-1,"PTE") -> 4 | T38: =IF(Q38="Entregado",IFERROR(IF(I38=VLOOKUP(I38,Valores!$K$1:$K$4,1,0),IF(S38<=VLOOKUP(I38,Valores!$K$1:$L$4,2,0),"Cumple","No cumple")),IF(S38<=VLOOKUP(K38,Valores!E:F,2,0),"Cumple","No cumple"))) -> No cumple | U38: =IFERROR(IF(T38="no cumple",S38-VLOOKUP(I38,Valores!$K$1:$L$4,2,0),0),S38-VLOOKUP(K38,Valores!E:F,2,0)) -> 1 | V38: Transporte | W38: 65353 | Y38: Demora en entrega
A39: 46036 | B39: enero | C39: 100267 | D39: Venta | E39: EFRALU SAS / DANIEL GARCIA | F39: TECU2CBC-77 | G39: =IFERROR(VLOOKUP(F39,Productos!$A$2:$D$277,2,0)," ") -> Cajonero 2.0 Bicolor Caramelo x77cm | H39: 1 | I39: =IFERROR(VLOOKUP(F39,Productos!$A$2:$D$277,3,0)," ") -> Archivador | J39: Bogotá y alrededores | K39: Bogotá | L39: =IF(O39>0,"Despachado","En alistamiento") -> Despachado | M39: Envía | N39: 4034508-954101379327 | O39: 46048 | P39: 46049 | Q39: =IF(P39>0,"Entregado","En transito") -> Entregado | R39: =IF(L39="Despachado",NETWORKDAYS.INTL(A39,O39,11,Valores!$A$2:$A$19)-1,"PTE") -> 10 | S39: =IF(Q39="Entregado",NETWORKDAYS.INTL(A39,P39,11,Valores!$A$2:$A$19)-1,"PTE") -> 11 | T39: =IF(Q39="Entregado",IFERROR(IF(I39=VLOOKUP(I39,Valores!$K$1:$K$4,1,0),IF(S39<=VLOOKUP(I39,Valores!$K$1:$L$4,2,0),"Cumple","No cumple")),IF(S39<=VLOOKUP(K39,Valores!E:F,2,0),"Cumple","No cumple"))) -> No cumple | U39: =IFERROR(IF(T39="no cumple",S39-VLOOKUP(I39,Valores!$K$1:$L$4,2,0),0),S39-VLOOKUP(K39,Valores!E:F,2,0)) -> 6 | V39: Producción | W39: 67823 | Y39: Disponibilidad materia prima
A40: 46036 | B40: enero | C40: 100268 | D40: Venta | E40: Nicolas Patiño Cañas | F40: TECUCT | G40: =IFERROR(VLOOKUP(F40,Productos!$A$2:$D$277,2,0)," ") -> Bandeja de cables | H40: 1 | I40: =IFERROR(VLOOKUP(F40,Productos!$A$2:$D$277,3,0)," ") -> Accesorio | J40: Bogotá y alrededores | K40: Bogotá | L40: =IF(O40>0,"Despachado","En alistamiento") -> Despachado | M40: Coordinadora | N40: 4029581-84151495795 | O40: 46045 | P40: 46048 | Q40: =IF(P40>0,"Entregado","En transito") -> Entregado | R40: =IF(L40="Despachado",NETWORKDAYS.INTL(A40,O40,11,Valores!$A$2:$A$19)-1,"PTE") -> 8 | S40: =IF(Q40="Entregado",NETWORKDAYS.INTL(A40,P40,11,Valores!$A$2:$A$19)-1,"PTE") -> 10 | T40: =IF(Q40="Entregado",IFERROR(IF(I40=VLOOKUP(I40,Valores!$K$1:$K$4,1,0),IF(S40<=VLOOKUP(I40,Valores!$K$1:$L$4,2,0),"Cumple","No cumple")),IF(S40<=VLOOKUP(K40,Valores!E:F,2,0),"Cumple","No cumple"))) -> No cumple | U40: =IFERROR(IF(T40="no cumple",S40-VLOOKUP(I40,Valores!$K$1:$L$4,2,0),0),S40-VLOOKUP(K40,Valores!E:F,2,0)) -> 7 | V40: Producción | W40: 26681 | Y40: Demora en proceso de producción
A41: 46036 | B41: enero | C41: 100268 | D41: Venta | E41: Nicolas Patiño Cañas | F41: TECUAN | G41: =IFERROR(VLOOKUP(F41,Productos!$A$2:$D$277,2,0)," ") -> Archivador TECU Negro | H41: 1 | I41: =IFERROR(VLOOKUP(F41,Productos!$A$2:$D$277,3,0)," ") -> Archivador | J41: Bogotá y alrededores | K41: Bogotá | L41: =IF(O41>0,"Despachado","En alistamiento") -> Despachado | M41: Envía | N41: 4029587-954101377984 | O41: 46045 | P41: 46046 | Q41: =IF(P41>0,"Entregado","En transito") -> Entregado | R41: =IF(L41="Despachado",NETWORKDAYS.INTL(A41,O41,11,Valores!$A$2:$A$19)-1,"PTE") -> 8 | S41: =IF(Q41="Entregado",NETWORKDAYS.INTL(A41,P41,11,Valores!$A$2:$A$19)-1,"PTE") -> 9 | T41: =IF(Q41="Entregado",IFERROR(IF(I41=VLOOKUP(I41,Valores!$K$1:$K$4,1,0),IF(S41<=VLOOKUP(I41,Valores!$K$1:$L$4,2,0),"Cumple","No cumple")),IF(S41<=VLOOKUP(K41,Valores!E:F,2,0),"Cumple","No cumple"))) -> No cumple | U41: =IFERROR(IF(T41="no cumple",S41-VLOOKUP(I41,Valores!$K$1:$L$4,2,0),0),S41-VLOOKUP(K41,Valores!E:F,2,0)) -> 4 | V41: Producción | W41: 57135 | Y41: Demora en proceso de producción
A42: 46037 | B42: enero | C42: 100269 | D42: Venta | E42: Juan Mayorga | F42: TECUTRM5C | G42: =IFERROR(VLOOKUP(F42,Productos!$A$2:$D$277,2,0)," ") -> Superficie Roble Miel 150x75 Clasico | H42: 1 | I42: =IFERROR(VLOOKUP(F42,Productos!$A$2:$D$277,3,0)," ") -> Superficie | J42: Antioquia | K42: El Retiro | L42: =IF(O42>0,"Despachado","En alistamiento") -> Despachado | M42: Envía | N42: 4034783-954101379381 | O42: 46048 | P42: 46050 | Q42: =IF(P42>0,"Entregado","En transito") -> Entregado | R42: =IF(L42="Despachado",NETWORKDAYS.INTL(A42,O42,11,Valores!$A$2:$A$19)-1,"PTE") -> 9 | S42: =IF(Q42="Entregado",NETWORKDAYS.INTL(A42,P42,11,Valores!$A$2:$A$19)-1,"PTE") -> 11 | T42: =IF(Q42="Entregado",IFERROR(IF(I42=VLOOKUP(I42,Valores!$K$1:$K$4,1,0),IF(S42<=VLOOKUP(I42,Valores!$K$1:$L$4,2,0),"Cumple","No cumple")),IF(S42<=VLOOKUP(K42,Valores!E:F,2,0),"Cumple","No cumple"))) -> No cumple | U42: =IFERROR(IF(T42="no cumple",S42-VLOOKUP(I42,Valores!$K$1:$L$4,2,0),0),S42-VLOOKUP(K42,Valores!E:F,2,0)) -> 6 | V42: Producción | W42: 43778 | Y42: Demora en proceso de pintura | Z42: Mónica estuvo enferma y se hizo la presentación de los nuevos Productos.
...

Sheet Productos
A1: PRODUCTOS
A2: CODIGO | B2: PRODUCTO | C2: Categoria | D2: Valores Fletes
A3: TECUTRM8M | B3: Superficie Roble Miel 180x75 Moderno | C3: Superficie | D3: 35000
A4: TECUTRM8C | B4: Superficie Roble Miel 180x75 Clasico | C4: Superficie | D4: 35000
A5: TECUTRM5C | B5: Superficie Roble Miel 150x75 Clasico | C5: Superficie | D5: 35000
A6: TECUTRC8C | B6: Superficie Roble Caramelo 180x70 Clasico | C6: Superficie | D6: 35000
A7: TECUTRC5C | B7: Superficie Roble Caramelo 150x70 Clasico | C7: Superficie | D7: 35000
A8: TECUTNE | B8: Superficie orden especial Color: Wengue | C8: Superficie | D8: 35000
A9: TECUTBE | B9: Superficie orden especial Color: Niebla | C9: Superficie | D9: 35000
A10: TECUTCCE | B10: Superficie orden especial Color: Miel | C10: Superficie | D10: 35000
A11: TECUTCOE | B11: Superficie orden especial Color: Caramelo | C11: Superficie | D11: 35000
A12: TECUTB20C | B12: Superficie Niebla 200x70 Clasico | C12: Superficie | D12: 35000
A13: TECUTB9C | B13: Superficie Niebla 190x70 Clasico | C13: Superficie | D13: 35000
A14: TECUTB8M | B14: Superficie Niebla 180x70 Moderno | C14: Superficie | D14: 35000
... A176: TECURCC | B176: Repisa Miel | C176: Repisa | D176: 25000
A177: TECURFB-80 | B177: Repisa Flotante Niebla x 80cm | C177: Repisa
A178: TECURFB-70 | B178: Repisa Flotante Niebla x 70cm | C178: Repisa
A179: TECURFB-60 | B179: Repisa Flotante Niebla x 60cm | C179: Repisa
A180: TECURFN-80 | B180: Repisa Flotante Negro x 80cm | C180: Repisa
A181: TECURFN-70 | B181: Repisa Flotante Negro x 70cm | C181: Repisa
A182: TECURFN-60 | B182: Repisa Flotante Negro x 60cm | C182: Repisa
A183: TECURFFE -80 | B183: Repisa Flotante Fresno Europeo x 80cm | C183: Repisa
A184: TECURFFE -70 | B184: Repisa Flotante Fresno Europeo x 70cm | C184: Repisa
A185: TECURFFE -60 | B185: Repisa Flotante Fresno Europeo x 60cm | C185: Repisa
A186: TECURFCO-80 | B186: Repisa Flotante Caramelo x 80cm | C186: Repisa
A187: TECURFCO-70 | B187: Repisa Flotante Caramelo x 70cm | C187: Repisa
A188: TECURFCO-60 | B188: Repisa Flotante Caramelo x 60cm | C188: Repisa
... A200: TECURECO-110 | B200: Repisa Escritorio Caramelo x 110cm | C200: Repisa
A201: TECURCO | B201: Repisa Caramelo | C201: Repisa | D201: 25000
A202: TECUBLS | B202: Laptop Stand B | C202: Accesorio | D202: 50000
A203: TECUFX-T76 | B203: Escritorio FIjo Linea - T x 76,5 cm | C203: Escritorio Fijo
A204: TECUFX-T72 | B204: Escritorio FIjo Linea - T x 72,5 cm | C204: Escritorio Fijo
A205: TECUFX-T68 | B205: Escritorio FIjo Linea - T x 68,5 cm | C205: Escritorio Fijo
A206: TECUFX-T64 | B206: Escritorio FIjo Linea - T x 64,5 cm | C206: Escritorio Fijo
A207: TECU2FNG | B207: Electric Standing Desk GO Negro | C207: Standing Desk | D207: 40000
A208: TECU2FGGO | B208: Electric Standing Desk GO Gris | C208: Standing Desk | D208: 40000
A209: TECU2FBGO | B209: Electric Standing Desk GO Blanco | C209: Standing Desk | D209: 40000
A210: TECULFG | B210: Electric Standing Desk En L Frame Gris | C210: Standing Desk | D210: 40000
A211: TECU3FNCRO | B211: Electric Standing Desk PRO Negro circular | C211: Standing Desk | D211: 40000
A212: TECU3FNPRO | B212: Electric Standing Desk PRO Negro | C212: Standing Desk | D212: 40000
...

Sheet Indicadores Despachos
A1: INDICADORES OPERACIÓN LOGISTICA TECU
A5: 1- TIEMPOS DE DESPACHO Y ENTREGA
A7: Mes | B7: mayo | L7: Mes | M7: mayo
A8: Status Despacho | B8: Despachado | L8: Status entrega | M8: Entregado
A10: Promedio de Tiempo de despacho de orden | B10: Categoria | L10: Promedio de Tiempo de entrega de la orden | M10: Categoria
A11: Ciudad | B11: Standing Desk | C11: Superficie | D11: Accesorio | E11: Archivador | F11: Repisa | G11: Silla | H11: Ruedas | L11: Ciudad | M11: Standing Desk | N11: Superficie | O11: Accesorio | P11: Archivador | Q11: Repisa | R11: Silla | S11: Ruedas
A12: Bogotá y alrededores | B12: 0.625 | C12: 0.6 | D12: 1 | E12: 2.6666667 | F12: 0 | G12: 0 | H12: 0 | L12: Bogotá y alrededores | M12: 2 | N12: 2.5333333 | O12: 2.4285714 | P12: 4 | Q12: 2 | R12: 1 | S12: 1
A13: Antioquia | B13: 0.5 | C13: 0.66666667 | D13: 1 | H13: 0 | L13: Antioquia | M13: 1.5 | N13: 1.6666667 | O13: 2 | S13: 1
A14: Valle del Cauca | B14: 0 | C14: 0 | L14: Valle del Cauca | M14: 1 | N14: 1
A15: Atlantico | D15: 0 | G15: 0 | L15: Atlantico | O15: 2 | R15: 2
A16: Santander | B16: 0 | C16: 0 | L16: Santander | M16: 2 | N16: 2
A17: Caldas | B17: 1 | C17: 1 | L17: Caldas | M17: 10 | N17: 11
A28: 2. TIEMPOS DE DESPACHO Y DE ENTREGAS POR CIUDAD
A31: Mes | B31: mayo
A32: Status entrega | B32: Entregado
A34: Promedio de Tiempo de entrega de la orden | B34: Categoria
A35: Ciudad | B35: Standing Desk | C35: Superficie | D35: Accesorio | E35: Archivador | F35: Repisa | G35: Silla | H35: Ruedas | I35: Instalacion
A36: Bogotá y alrededores | B36: 2 | C36: 2.5333333 | D36: 2.4285714 | E36: 4 | F36: 2 | G36: 1 | H36: 1 | I36: #VALUE!
A37: Antioquia | B37: 1.5 | C37: 1.6666667 | D37: 2 | H37: 1 | I37: #VALUE!
A38: Valle del Cauca | B38: 1 | C38: 1
A39: Atlantico | D39: 2 | G39: 2
A40: Santander | B40: 2 | C40: 2
A41: Caldas | B41: 10 | C41: 11

Sheet OKR
A1: Indicador OTIF | E1: =D2*E31 -> 961.97778
A2: 1 a 3 días Ciudades principales 1 a 5 días Ciudades Secundarias | D2: =B13/(B13+C13) -> 0.81111111 | E2: NNS
J3: Enero | K3: 36
A4: Concepto | B4: Venta | J4: Garantias | K4: 6
A5: Status entrega | B5: Entregado | J5: A tiempo | K5: 20
J6: Fill rate | K6: =(K3-K4)/K3 -> 0.83333333
A7: Cuenta de No orden | B7: Cumple NNS
A8: Mes | B8: Cumple | C8: No cumple | D8: (en blanco) | E8: #N/D | F8: #¡VALOR! | G8: Total general | J8: OTIF | K8: =(K3-K4-K5)/K3 -> 0.27777778
A9: enero | B9: 70 | C9: 25 | G9: 95
A10: febrero | B10: 86 | C10: 5 | G10: 91
A11: marzo | B11: 60 | C11: 5 | G11: 65
A12: abril | B12: 111 | C12: 24 | E12: 3 | G12: 138
A13: mayo | B13: 73 | C13: 17 | E13: 12 | G13: 102
A14: junio | B14: 80 | C14: 8 | E14: 5 | G14: 93
A15: julio | B15: 80 | C15: 16 | E15: 9 | G15: 105
A16: agosto | B16: 44 | C16: 19 | E16: 6 | G16: 69
A17: septiembre | B17: 50 | C17: 12 | E17: 3 | F17: 2 | G17: 67
A18: octubre | B18: 76 | C18: 12 | E18: 12 | F18: 1 | G18: 101
A19: noviembre | B19: 115 | C19: 31 | E19: 12 | G19: 158
A20: diciembre | B20: 49 | C20: 30 | D20: 1 | E20: 3 | G20: 83
A21: Total general | B21: 894 | C21: 204 | D21: 1 | E21: 65 | F21: 3 | G21: 1167
A31: Garantias | E31: =B37/$B$38 -> 1186
A32: Mes | B32: (Todas)
A34: Cuenta de No orden
A35: Concepto | B35: Total
A36: Garantia | B36: 13
A37: Venta | B37: 1186
A38: RIFA | B38: 1
A39: Préstamo | B39: 4
A40: Cortesia | B40: 4
A41: Cambio | B41: 1
A42: Politica Satisfaccion | B42: 1
A43: Total general | B43: 1210
C47: Stock minimo
A48: Descripcion del producto | B48: Promedio mes | C48: n+4 | D48: Inventario actual | E48: COSTO | F48: FI | G48: TRM | H48: Costo
A49: Electric Standing Desk GO Negro | B49: 17 | C49: =B49*4 -> 68 | D49: 79 | E49: 122 | F49: 1.46 | G49: 4444.36 | H49: =((E49*F49)*G49)*D49 -> 62538723
A50: Electric Standing Desk GO Gris | B50: 2 | C50: =B50*4 -> 8 | D50: 0 | E50: 122 | F50: 1.46 | G50: 4444.36 | H50: =((E50*F50)*G50)*D50 -> 0
A51: Electric Standing Desk GO Blanco | B51: 4 | C51: =B51*4 -> 16 | D51: 21 | E51: 122 | F51: 1.46 | G51: 4444.36 | H51: =((E51*F51)*G51)*D51 -> 16624217
A52: Electric Standing Desk PRO Negro | B52: 15 | C52: 60 | D52: 58 | E52: 125 | F52: 1.46 | G52: 4444.36 | H52: =((E52*F52)*G52)*D52 -> 47043551
A53: Electric Standing Desk PRO Negro circular | B53: 15 | C53: 60 | D53: 15 | E53: 125 | F53: 1.46 | G53: 4444.36 | H53: =((E53*F53)*G53)*D53 -> 12166436
...

Sheet Analisis Ventas
B2: INDICADORES VENTAS TECU.CO
A4: 1. RESUMEN DE VENTAS
A5: Concepto | B5: Venta
A7: Suma de Cantidad | B7: Categoria
A8: Mes | B8: Standing Desk | C8: Superficie | D8: Accesorio | E8: Archivador | F8: Repisa | G8: Silla | H8: Instalación | I8: Fijo | J8: Total general
A9: enero | B9: 23 | C9: 21 | D9: 15 | E9: 7 | F9: 7 | G9: 1 | H9: 4 | J9: 78
A10: febrero | B10: 17 | C10: 16 | D10: 9 | E10: 3 | F10: 4 | H10: 1 | I10: 3 | J10: 53
A11: Total general | B11: 40 | C11: 37 | D11: 24 | E11: 10 | F11: 11 | G11: 1 | H11: 5 | I11: 3 | J11: 131
E12: **Variacion porcentual
B13: =(B10-B9)/B9 -> -0.26086957 | C13: =(C10-C9)/C9 -> -0.23809524 | D13: =(D10-D9)/D9 -> -0.4 | E13: =(E10-E9)/E9 -> -0.57142857 | F13: =(F10-F9)/F9 -> -0.42857143 | G13: =(G10-G9)/G9 -> -1 | H13: =(H10-H9)/H9 -> -0.75 | I13: =(I10-I9)/I9 -> #DIV/0! | J13: =(J10-J9)/J9 -> -0.32051282
A25: Mes | B25: (Todas)
A26: Concepto | B26: Venta
A28: Suma de Cantidad | B28: Categoria
A29: Ciudad | B29: Standing Desk | C29: Superficie | D29: Repisa | E29: Accesorio | F29: Archivador | G29: Silla | H29: Instalación | I29: Fijo | J29: Total general
A30: Bogotá y alrededores | B30: 21 | C30: 20 | D30: 6 | E30: 13 | F30: 4 | H30: 4 | I30: 3 | J30: 71
A31: Antioquia | B31: 9 | C31: 8 | E31: 4 | F31: 2 | H31: 1 | J31: 24
A32: Tolima | B32: 1 | C32: 1 | D32: 2 | E32: 5 | G32: 1 | J32: 10
A33: Quindío | B33: 3 | C33: 3 | F33: 3 | J33: 9
A34: Valle del Cauca | B34: 2 | C34: 2 | D34: 1 | E34: 1 | F34: 1 | J34: 7
A35: Cesar | B35: 1 | C35: 1 | D35: 1 | J35: 3
A36: Meta | B36: 1 | C36: 1 | J36: 2
A37: Cauca | B37: 1 | C37: 1 | J37: 2
A38: Bolívar | D38: 1 | J38: 1
A39: Cundinamarca | E39: 1 | J39: 1
A40: Caldas | B40: 1 | J40: 1
A41: Total general | B41: 40 | C41: 37 | D41: 11 | E41: 24 | F41: 10 | G41: 1 | H41: 5 | I41: 3 | J41: 131
A78: Mes | B78: (Todas)
A79: Concepto | B79: Venta
A81: Suma de Cantidad | B81: Categoria
A82: Lugar de entrega | B82: Standing Desk | C82: Superficie | D82: Repisa | E82: Accesorio | F82: Archivador | G82: Silla | H82: Instalación | I82: Fijo | J82: Total general
A83: Bogotá | B83: 21 | C83: 20 | D83: 6 | E83: 11 | F83: 4 | H83: 4 | I83: 3 | J83: 69
A84: Medellín | B84: 5 | C84: 5 | E84: 2 | H84: 1 | J84: 13
A85: Ibagué | B85: 1 | C85: 1 | D85: 2 | E85: 5 | G85: 1 | J85: 10
A86: Armenia | B86: 3 | C86: 3 | F86: 3 | J86: 9
A87: Jamundí | B87: 1 | C87: 1 | D87: 1 | E87: 1 | J87: 4
A88: Sabaneta | B88: 1 | C88: 1 | F88: 2 | J88: 4
A89: Valledupar | B89: 1 | C89: 1 | D89: 1 | J89: 3
A90: El Retiro | B90: 1 | C90: 1 | E90: 1 | J90: 3
A91: Chía | E91: 2 | J91: 2
A92: Itagui | B92: 1 | C92: 1 | J92: 2
...

Sheet Valores
A1: dias Festivos | D1: Ciudad entrega | E1: Lugar entrega | F1: Tiempo entrega | H1: Concepto | K1: Concepto | L1: Dias entrega | O1: Causales de incumplimiento
A2: 46023 | D2: Acacias | E2: Meta | F2: 5 | H2: Venta | K2: Bibliotecas | L2: 15 | O2: Demora en proceso de pintura
A3: 46034 | D3: Aguachica | E3: Aguachica | F3: 5 | H3: Garantia | K3: Fijo | L3: 10 | O3: Demora en proceso de producción
A4: 46104 | D4: Antioquia | E4: Envigado | F4: 3 | H4: Cortesia | K4: Archivador | L4: 5 | O4: Demora en proceso de producción- Novedad en el reparto
A5: 46114 | D5: Antioquia | E5: Medellín | F5: 3 | H5: Novedad | O5: Disponibilidad materia prima
A6: 46115 | D6: Antioquia | E6: Bello | F6: 3 | O6: Ausencia del cliente
A7: 46143 | D7: Antioquia | E7: Sabaneta | F7: 3 | O7: Demora en entrega
A8: 46160 | D8: Antioquia | E8: La estrella | F8: 3
A9: 46181 | D9: Antioquia | E9: El retiro | F9: 5
A10: 46188 | D10: Antioquia | E10: Caldas | F10: 5
A11: 46202 | D11: Antioquia | E11: La ceja | F11: 5
A12: 46223 | D12: Antioquia | E12: Itagui | F12: 3
A13: 46241 | D13: Antioquia | E13: Rionegro | F13: 3
A14: 46251 | D14: Antioquia | E14: Guarne | F14: 5
A15: 46307 | D15: Antioquia | E15: Carmen de Viboral | F15: 5
A16: 46328 | D16: Antioquia | E16: Retiro | F16: 5
A17: 46342 | D17: Antioquia | E17: San Vicente | F17: 5
A18: 46364 | D18: Antioquia | E18: Marinilla | F18: 5
A19: 46381 | D19: Antioquia | E19: Copacabana | F19: 5
D20: Quindio | E20: Armenia | F20: 3
D21: Atlantico | E21: Soledad | F21: 5
D22: Atlantico | E22: Barranquilla | F22: 5
D23: Bogotá y alrededores | E23: Bogotá | F23: 3
D24: Bogotá y alrededores | E24: Cajica | F24: 5
D25: Bogotá y alrededores | E25: Bojaca | F25: 5
D26: Bogotá y alrededores | E26: Zipaquira | F26: 5
D27: Bogotá y alrededores | E27: Choachi | F27: 5
D28: Bogotá y alrededores | E28: Chía | F28: 5
D29: Bogotá y alrededores | E29: Fusagasuga | F29: 5
D30: Bogotá y alrededores | E30: Mosquera | F30: 5
D31: Bogotá y alrededores | E31: Tocancipa | F31: 5
... D67: Santander | E67: Barrancabermeja | F67: 5

Sheet Graficos Finales
A1: Mes | B1: Standing Desk | C1: Superficie | D1: Accesorio | E1: Archivador | F1: Repisa | G1: Silla | H1: Ruedas | I1: Instalaciones | J1: Total general
A2: Diciembre | B2: 30 | C2: 31 | D2: 10 | E2: 9 | F2: 6 | G2: 2 | I2: 7 | J2: =SUM(B2:I2) -> 95
A3: Enero | B3: 40 | C3: 35 | D3: 18 | E3: 2 | F3: 3 | G3: 3 | H3: 4 | I3: 10 | J3: 115 | K3: =(B3-B2)/B2 -> 0.33333333
A4: Febrero | B4: 22 | C4: 20 | D4: 10 | E4: 7 | F4: 1 | H4: 4 | I4: 2 | J4: 66 | K4: =(B4-B3)/B3 -> -0.45
A5: Marzo | B5: 35 | C5: 36 | D5: 7 | E5: 3 | F5: 4 | H5: 3 | I5: 7 | J5: 95 | K5: =(B5-B4)/B4 -> 0.59090909
A6: Abril | B6: 35 | C6: 33 | D6: 16 | E6: 3 | F6: 3 | G6: 5 | H6: 3 | I6: 7 | J6: 105 | K6: =(B6-B5)/B5 -> 0
A7: Mayo | B7: 25 | C7: 24 | D7: 12 | E7: 4 | F7: 1 | G7: 4 | H7: 4 | I7: 6 | J7: 80 | K7: =(B7-B6)/B6 -> -0.28571429
A8: Total general | B8: =SUM(B2:B5) -> 127 | C8: =SUM(C2:C5) -> 122 | D8: =SUM(D2:D5) -> 45 | E8: =SUM(E2:E5) -> 21 | F8: =SUM(F2:F5) -> 14 | G8: =SUM(G2:G5) -> 5 | H8: =SUM(H2:H5) -> 11 | I8: =SUM(I2:I5) -> 26 | J8: =SUM(J2:J5) -> 371
A13: Ventas por Lugar de entrega
A15: Ciudad | B15: Standing Desk | C15: Superficie | D15: Repisa | E15: Accesorio | F15: Archivador | G15: Silla | H15: Ruedas | I15: Instalacion | J15: Total general
A16: Bogotá y alrededores | B16: 16 | C16: 16 | D16: 1 | E16: 10 | F16: 4 | G16: 2 | H16: 2 | I16: 4 | J16: 55
A17: Antioquia | B17: 4 | C17: 3 | E17: 1 | H17: 2 | I17: 2 | J17: 12 | M17: Ciudad | N17: Standing Desk
A18: Valle del Cauca | B18: 3 | C18: 3 | J18: 6 | M18: Bogotá y alrededores | N18: 55
A19: Atlantico | E19: 1 | G19: 2 | J19: 3 | M19: Antioquia | N19: 12
A20: Caldas | B20: 1 | C20: 1 | J20: 2 | M20: Valle del Cauca | N20: 6
A21: Santander | B21: 1 | C21: 1 | J21: 2 | M21: Atlantico | N21: 3
A22: Total general | B22: 25 | C22: 24 | D22: 1 | E22: 12 | F22: 4 | G22: 4 | H22: 4 | I22: 6 | J22: 80 | M22: Caldas | N22: 2
M23: Santander | N23: 2
M24: Total general | N24: 80
A34: Ventas por Ciudad
A36: Suma de Cantidad | B36: Categoria | M36: Lugar de entrega | N36: Qty Ventas
A37: Lugar de entrega | B37: Standing Desk | C37: Superficie | D37: Repisa | E37: Accesorio | F37: Archivador | G37: Silla | H37: Ruedas | I37: Instalacion | J37: Total general | M37: Bogota | N37: 45
A38: Bogota | B38: 13 | C38: 13 | E38: 8 | F38: 3 | G38: 2 | H38: 2 | I38: 4 | J38: 45 | M38: Medellin | N38: 6
A39: Medellin | B39: 2 | C39: 1 | E39: 1 | I39: 2 | J39: 6 | M39: Chia | N39: 4
A40: Chia | B40: 1 | C40: 1 | E40: 1 | F40: 1 | J40: 4 | M40: Cali | N40: 4
A41: Cali | B41: 2 | C41: 2 | J41: 4 | M41: Barranquilla | N41: 3
A42: Barranquilla | E42: 1 | G42: 2 | J42: 3 | M42: Funza | N42: 2
A43: Funza | B43: 1 | C43: 1 | J43: 2 | M43: Retiro | N43: 2
A44: Retiro | B44: 1 | C44: 1 | J44: 2 | M44: Soacha | N44: 2
A45: Soacha | B45: 1 | C45: 1 | J45: 2 | M45: Envigado | N45: 2
A46: Envigado | H46: 2 | J46: 2 | M46: Palmira | N46: 2
A47: Palmira | B47: 1 | C47: 1 | J47: 2 | M47: Cajica | N47: 2
A48: Cajica | D48: 1 | E48: 1 | J48: 2 | M48: Bucaramanga | N48: 2
A49: Bucaramanga | B49: 1 | C49: 1 | J49: 2 | M49: Manizales | N49: 2
A50: Manizales | B50: 1 | C50: 1 | J50: 2 | M50: Carmen de Viboral | N50: 2
A51: Carmen de Viboral | B51: 1 | C51: 1 | J51: 2 | M51: Total general | N51: 80
A52: Total general | B52: 25 | C52: 24 | D52: 1 | E52: 12 | F52: 4 | G52: 4 | H52: 4 | I52: 6 | J52: 80
A65: TIEMPO DESPACHO
J67: Ciudad | K67: Standing Desk | L67: Superficie
A68: Ciudad | B68: Standing Desk | C68: Superficie | D68: Accesorio | E68: Archivador | F68: Repisa | G68: Silla | H68: Ruedas | J68: Bogotá y alrededores | K68: 0.625 | L68: 0.6
...

Sheet Graficos causales
A3: Cuenta de No orden | B3: Etiquetas de columna
A4: Etiquetas de fila | B4: enero | C4: Total general
A5: Cumple | B5: 49 | C5: 49
A6: No cumple | B6: 23 | C6: 23
A7: Total general | B7: 72 | C7: 72
A17: Cumple NNS | B17: No cumple
A19: Cuenta de No orden | B19: Etiquetas de columna
A20: Etiquetas de fila | B20: enero | C20: Total general
A21: Demora en proceso de producción | B21: 6 | C21: 6 | D21: =B21/$B$27 -> 0.26086957
A22: Disponibilidad materia prima | B22: 6 | C22: 6 | D22: =B22/$B$27 -> 0.26086957
A23: Demora en proceso de pintura | B23: 5 | C23: 5 | D23: =B23/$B$27 -> 0.2173913
A24: Demora en entrega | B24: 3 | C24: 3 | D24: =B24/$B$27 -> 0.13043478
A25: Ausencia del cliente | B25: 2 | C25: 2 | D25: =B25/$B$27 -> 0.086956522
A26: Demora en proceso de producción- Novedad en el reparto | B26: 1 | C26: 1 | D26: =B26/$B$27 -> 0.043478261
A27: Total general | B27: 23 | C27: 23 | D27: =B27/$B$27 -> 1
A33: Cumple NNS | B33: No cumple
A35: Cuenta de No orden | B35: Etiquetas de columna
A36: Etiquetas de fila | B36: enero | C36: Total general
A37: Cliente | B37: 2 | C37: 2
A38: Producción | B38: 16 | C38: 16
A39: Producción - Transporte | B39: 4 | C39: 4
A40: Transporte | B40: 1 | C40: 1
A41: Total general | B41: 23 | C41: 23
