Workbook

Sheet Base Ventas
A1: BASE VENTAS Y DESPACHOS 2025
A4: Fecha | B4: Mes | C4: No orden | D4: Concepto | E4: Cliente/Proveedor | F4: Codigo | G4: Descripcion del producto | H4: Cantidad | I4: Categoria | J4: Ciudad | K4: Lugar de entrega | L4: Status Despacho | M4: Transportadora | N4: No guia | O4: Fecha de despacho | P4: Fecha de Entrega | Q4: Status entrega | R4: Tiempo de despacho de orden | S4: Tiempo de entrega de la orden | T4: Tiempo de Desvío Despacho | U4: Tiempo de Desvío Entrega | V4: Cumple NNS | W4: Desvío NNS (Hábil) | X4: Valor despacho | Y4: Qué área incumple | Z4: Diferencia valor real vs Estimado | AA4: Observaciones
A5: 45658 | B5: =TEXT(A5,"mmmm") -> enero | C5: 2377 | D5: Venta | E5: Cata Gómez | F5: TECUBDPM | G5: =IFERROR(VLOOKUP(F5,Productos!$A$2:$D$258,2,0)," ") -> Desk Pad B Negro Café Miel | H5: 1 | I5: =IFERROR(VLOOKUP(F5,Productos!$A$2:$D$258,3,0)," ") -> Accesorio | J5: Antioquia | K5: La estrella | L5: =IF(O5>0,"Despachado","En alistamiento") -> Despachado | M5: Coordinadora | N5: 3002937 -84151097246 | O5: 45664 | P5: 45665 | Q5: =IF(P5>0,"Entregado","En transito") -> Entregado | R5: =IF(L5="Despachado",NETWORKDAYS.INTL("07/01/2025",O5,11,Valores!$A$2:$A$18)-1,"PTE") -> 0 | S5: =IF(Q5="Entregado",NETWORKDAYS.INTL("07/01/2025",P5,11,Valores!$A$2:$A$18)-1,"PTE") -> 1 | V5: =IF(Q5="Entregado",IF(S5<=VLOOKUP(K5,Valores!E:F,2,0),"Cumple","No cumple"),"PTE") -> Cumple | X5: 16617 | AA5: Vacaciones TECU
A6: 45659 | B6: =TEXT(A6,"mmmm") -> enero | C6: 2378 | D6: Venta | E6: Andres felipe Carreño | F6: TECUBDPA | G6: =IFERROR(VLOOKUP(F6,Productos!$A$2:$D$258,2,0)," ") -> Desk Pad B Negro Azul | H6: 1 | I6: =IFERROR(VLOOKUP(F6,Productos!$A$2:$D$258,3,0)," ") -> Accesorio | J6: Bogotá y alrededores | K6: Bogota | L6: =IF(O6>0,"Despachado","En alistamiento") -> Despachado | M6: Coordinadora | N6: 3002977 -84151097273 | O6: 45664 | P6: 45665 | Q6: =IF(P6>0,"Entregado","En transito") -> Entregado | R6: =IF(L6="Despachado",NETWORKDAYS.INTL("07/01/2025",O6,11,Valores!$A$2:$A$18)-1,"PTE") -> 0 | S6: =IF(Q6="Entregado",NETWORKDAYS.INTL("07/01/2025",P6,11,Valores!$A$2:$A$18)-1,"PTE") -> 1 | V6: =IF(Q6="Entregado",IF(S6<=VLOOKUP(K6,Valores!E:F,2,0),"Cumple","No cumple"),"PTE") -> Cumple | X6: 16617 | AA6: Vacaciones TECU
A7: 45663 | B7: =TEXT(A7,"mmmm") -> enero | C7: 2379 | D7: Venta | E7: Juan Guevara | F7: TECU2FBGO | G7: =IFERROR(VLOOKUP(F7,Productos!$A$2:$D$258,2,0)," ") -> Electric Standing Desk GO Blanco | H7: 1 | I7: =IFERROR(VLOOKUP(F7,Productos!$A$2:$D$258,3,0)," ") -> Standing Desk | J7: Bogotá y alrededores | K7: Bogota | L7: =IF(O7>0,"Despachado","En alistamiento") -> Despachado | M7: Coordinadora | N7: 3006333 -84151099203 | O7: 45665 | P7: 45667 | Q7: =IF(P7>0,"Entregado","En transito") -> Entregado | R7: =IF(L7="Despachado",NETWORKDAYS.INTL(A7,O7,11,Valores!$A$2:$A$18)-1,"PTE") -> 1 | S7: =IF(Q7="Entregado",NETWORKDAYS.INTL(A7,P7,11,Valores!$A$2:$A$18)-1,"PTE") -> 3 | V7: =IF(Q7="Entregado",IF(S7<=VLOOKUP(K7,Valores!E:F,2,0),"Cumple","No cumple"),"PTE") -> Cumple | X7: 41593
A8: 45663 | B8: =TEXT(A8,"mmmm") -> enero | C8: 2379 | D8: Venta | E8: Juan Guevara | F8: TECUTFE2C | G8: =IFERROR(VLOOKUP(F8,Productos!$A$2:$D$258,2,0)," ") -> Superficie Fresno Europeo 120x70 Clasico Small | H8: 1 | I8: =IFERROR(VLOOKUP(F8,Productos!$A$2:$D$258,3,0)," ") -> Superficie | J8: Bogotá y alrededores | K8: Bogota | L8: =IF(O8>0,"Despachado","En alistamiento") -> Despachado | M8: Coordinadora | N8: 3006334 -84151099205 | O8: 45665 | P8: 45667 | Q8: =IF(P8>0,"Entregado","En transito") -> Entregado | R8: =IF(L8="Despachado",NETWORKDAYS.INTL(A8,O8,11,Valores!$A$2:$A$18)-1,"PTE") -> 1 | S8: =IF(Q8="Entregado",NETWORKDAYS.INTL(A8,P8,11,Valores!$A$2:$A$18)-1,"PTE") -> 3 | V8: =IF(Q8="Entregado",IF(S8<=VLOOKUP(K8,Valores!E:F,2,0),"Cumple","No cumple"),"PTE") -> Cumple | X8: 24093
A9: 45663 | B9: =TEXT(A9,"mmmm") -> enero | C9: 2379 | D9: Venta | E9: Juan Guevara | F9: TECUCT | G9: =IFERROR(VLOOKUP(F9,Productos!$A$2:$D$258,2,0)," ") -> Bandeja de cables | H9: 1 | I9: =IFERROR(VLOOKUP(F9,Productos!$A$2:$D$258,3,0)," ") -> Accesorio | J9: Bogotá y alrededores | K9: Bogota | L9: =IF(O9>0,"Despachado","En alistamiento") -> Despachado | M9: Coordinadora | N9: 3006341 -84151099209 | O9: 45665 | P9: 45667 | Q9: =IF(P9>0,"Entregado","En transito") -> Entregado | R9: =IF(L9="Despachado",NETWORKDAYS.INTL(A9,O9,11,Valores!$A$2:$A$18)-1,"PTE") -> 1 | S9: =IF(Q9="Entregado",NETWORKDAYS.INTL(A9,P9,11,Valores!$A$2:$A$18)-1,"PTE") -> 3 | V9: =IF(Q9="Entregado",IF(S9<=VLOOKUP(K9,Valores!E:F,2,0),"Cumple","No cumple"),"PTE") -> Cumple | X9: 24885
A10: 45663 | B10: =TEXT(A10,"mmmm") -> enero | C10: 2380 | D10: Venta | E10: Juan Carlos Urbano | F10: TECU2FNG | G10: =IFERROR(VLOOKUP(F10,Productos!$A$2:$D$258,2,0)," ") -> Electric Standing Desk GO Negro | H10: 1 | I10: =IFERROR(VLOOKUP(F10,Productos!$A$2:$D$258,3,0)," ") -> Standing Desk | J10: Bogotá y alrededores | K10: Bogota | L10: =IF(O10>0,"Despachado","En alistamiento") -> Despachado | M10: Coordinadora | N10: 3003131 -84151097381 | O10: 45664 | P10: 45665 | Q10: =IF(P10>0,"Entregado","En transito") -> Entregado | R10: =IF(L10="Despachado",NETWORKDAYS.INTL(A10,O10,11,Valores!$A$2:$A$18)-1,"PTE") -> 0 | S10: =IF(Q10="Entregado",NETWORKDAYS.INTL(A10,P10,11,Valores!$A$2:$A$18)-1,"PTE") -> 1 | V10: =IF(Q10="Entregado",IF(S10<=VLOOKUP(K10,Valores!E:F,2,0),"Cumple","No cumple"),"PTE") -> Cumple | X10: 41593
A11: 45663 | B11: =TEXT(A11,"mmmm") -> enero | C11: 2380 | D11: Venta | E11: Juan Carlos Urbano | F11: TECUTCO4C | G11: =IFERROR(VLOOKUP(F11,Productos!$A$2:$D$258,2,0)," ") -> Superficie Caramelo 140x70 Clasico | H11: 1 | I11: =IFERROR(VLOOKUP(F11,Productos!$A$2:$D$258,3,0)," ") -> Superficie | J11: Bogotá y alrededores | K11: Bogota | L11: =IF(O11>0,"Despachado","En alistamiento") -> Despachado | M11: Coordinadora | N11: 3003134 -84151097383 | O11: 45664 | P11: 45666 | Q11: =IF(P11>0,"Entregado","En transito") -> Entregado | R11: =IF(L11="Despachado",NETWORKDAYS.INTL(A11,O11,11,Valores!$A$2:$A$18)-1,"PTE") -> 0 | S11: =IF(Q11="Entregado",NETWORKDAYS.INTL(A11,P11,11,Valores!$A$2:$A$18)-1,"PTE") -> 2 | V11: =IF(Q11="Entregado",IF(S11<=VLOOKUP(K11,Valores!E:F,2,0),"Cumple","No cumple"),"PTE") -> Cumple | X11: 24093
A12: 45663 | B12: =TEXT(A12,"mmmm") -> enero | C12: 2380 | D12: Venta | E12: Juan Carlos Urbano | F12: TECUCT | G12: =IFERROR(VLOOKUP(F12,Productos!$A$2:$D$258,2,0)," ") -> Bandeja de cables | H12: 1 | I12: =IFERROR(VLOOKUP(F12,Productos!$A$2:$D$258,3,0)," ") -> Accesorio | J12: Bogotá y alrededores | K12: Bogota | L12: =IF(O12>0,"Despachado","En alistamiento") -> Despachado | M12: Coordinadora | N12: 3003144 -84151097390 | O12: 45664 | P12: 45666 | Q12: =IF(P12>0,"Entregado","En transito") -> Entregado | R12: =IF(L12="Despachado",NETWORKDAYS.INTL(A12,O12,11,Valores!$A$2:$A$18)-1,"PTE") -> 0 | S12: =IF(Q12="Entregado",NETWORKDAYS.INTL(A12,P12,11,Valores!$A$2:$A$18)-1,"PTE") -> 2 | V12: =IF(Q12="Entregado",IF(S12<=VLOOKUP(K12,Valores!E:F,2,0),"Cumple","No cumple"),"PTE") -> Cumple | X12: 24885
A13: 45663 | B13: =TEXT(A13,"mmmm") -> enero | C13: 2381 | D13: Venta | E13: Julian Cujabante Villamil | F13: TECULFN2 | G13: =IFERROR(VLOOKUP(F13,Productos!$A$2:$D$258,2,0)," ") -> Electric Standing Desk En L Frame Negro 2.0 | H13: 1 | I13: =IFERROR(VLOOKUP(F13,Productos!$A$2:$D$258,3,0)," ") -> Standing Desk | J13: Bogotá y alrededores | K13: Bogota | L13: =IF(O13>0,"Despachado","En alistamiento") -> Despachado | M13: Coordinadora | N13: 3006368 -84151099224 | O13: 45665 | P13: 45667 | Q13: =IF(P13>0,"Entregado","En transito") -> Entregado | R13: =IF(L13="Despachado",NETWORKDAYS.INTL(A13,O13,11,Valores!$A$2:$A$18)-1,"PTE") -> 1 | S13: =IF(Q13="Entregado",NETWORKDAYS.INTL(A13,P13,11,Valores!$A$2:$A$18)-1,"PTE") -> 3 | V13: =IF(Q13="Entregado",IF(S13<=VLOOKUP(K13,Valores!E:F,2,0),"Cumple","No cumple"),"PTE") -> Cumple | X13: 62530
A14: 45663 | B14: =TEXT(A14,"mmmm") -> enero | C14: 2381 | D14: Venta | E14: Julian Cujabante Villamil | F14: TECUTLRNS | G14: =IFERROR(VLOOKUP(F14,Productos!$A$2:$D$258,2,0)," ") -> Superficie en L Roble Negro 180x150cm x 70 | H14: 1 | I14: =IFERROR(VLOOKUP(F14,Productos!$A$2:$D$258,3,0)," ") -> Superficie | J14: Bogotá y alrededores | K14: Bogota | L14: =IF(O14>0,"Despachado","En alistamiento") -> Despachado | M14: Coordinadora | N14: 3006370 -84151099227 | O14: 45665 | P14: 45667 | Q14: =IF(P14>0,"Entregado","En transito") -> Entregado | R14: =IF(L14="Despachado",NETWORKDAYS.INTL(A14,O14,11,Valores!$A$2:$A$18)-1,"PTE") -> 1 | S14: =IF(Q14="Entregado",NETWORKDAYS.INTL(A14,P14,11,Valores!$A$2:$A$18)-1,"PTE") -> 3 | V14: =IF(Q14="Entregado",IF(S14<=VLOOKUP(K14,Valores!E:F,2,0),"Cumple","No cumple"),"PTE") -> Cumple | X14: 26749
A15: 45663 | B15: =TEXT(A15,"mmmm") -> enero | C15: 2381 | D15: Venta | E15: Julian Cujabante Villamil | F15: TECUCT | G15: =IFERROR(VLOOKUP(F15,Productos!$A$2:$D$258,2,0)," ") -> Bandeja de cables | H15: 1 | I15: =IFERROR(VLOOKUP(F15,Productos!$A$2:$D$258,3,0)," ") -> Accesorio | J15: Bogotá y alrededores | K15: Bogota | L15: =IF(O15>0,"Despachado","En alistamiento") -> Despachado | M15: Coordinadora | N15: 3006387 -84151099241 | O15: 45665 | P15: 45666 | Q15: =IF(P15>0,"Entregado","En transito") -> Entregado | R15: =IF(L15="Despachado",NETWORKDAYS.INTL(A15,O15,11,Valores!$A$2:$A$18)-1,"PTE") -> 1 | S15: =IF(Q15="Entregado",NETWORKDAYS.INTL(A15,P15,11,Valores!$A$2:$A$18)-1,"PTE") -> 2 | V15: =IF(Q15="Entregado",IF(S15<=VLOOKUP(K15,Valores!E:F,2,0),"Cumple","No cumple"),"PTE") -> Cumple | X15: 24885
A16: 45663 | B16: =TEXT(A16,"mmmm") -> enero | C16: 2381 | D16: Venta | E16: Julian Cujabante Villamil | F16: TECUTBANPI | G16: =IFERROR(VLOOKUP(F16,Productos!$A$2:$D$258,2,0)," ") -> Bandeja Piano | H16: 1 | I16: =IFERROR(VLOOKUP(F16,Productos!$A$2:$D$258,3,0)," ") -> Accesorio | J16: Bogotá y alrededores | K16: Bogota | L16: =IF(O16>0,"Despachado","En alistamiento") -> Despachado | M16: Coordinadora | N16: 3006380 -84151099237 | O16: 45665 | P16: 45667 | Q16: =IF(P16>0,"Entregado","En transito") -> Entregado | R16: =IF(L16="Despachado",NETWORKDAYS.INTL(A16,O16,11,Valores!$A$2:$A$18)-1,"PTE") -> 1 | S16: =IF(Q16="Entregado",NETWORKDAYS.INTL(A16,P16,11,Valores!$A$2:$A$18)-1,"PTE") -> 3 | V16: =IF(Q16="Entregado",IF(S16<=VLOOKUP(K16,Valores!E:F,2,0),"Cumple","No cumple"),"PTE") -> Cumple | X16: 39225
A17: 45663 | B17: =TEXT(A17,"mmmm") -> enero | C17: 2381 | D17: Venta | E17: Julian Cujabante Villamil | G17: Servicio de instalacion | H17: 1 | I17: Instalacion | J17: Bogotá y alrededores | K17: Bogota | L17: Instalacion | M17: NA | N17: NA | O17: NA | P17: NA | Q17: =IF(P17>0,"Entregado","En transito") -> Entregado | R17: =IF(L17="Despachado",NETWORKDAYS.INTL(A17,O17,11,Valores!$A$2:$A$18)-1,"PTE") -> PTE | S17: =IF(Q17="Entregado",NETWORKDAYS.INTL(A17,P17,11,Valores!$A$2:$A$18)-1,"PTE") -> #VALUE! | V17: =IF(Q17="Entregado",IF(S17<=VLOOKUP(K17,Valores!E:F,2,0),"Cumple","No cumple"),"PTE") -> #VALUE! | X17: 0
A18: 45664 | B18: =TEXT(A18,"mmmm") -> enero | C18: 2382 | D18: Venta | E18: Henry De Alba | F18: TECU2FNG | G18: =IFERROR(VLOOKUP(F18,Productos!$A$2:$D$258,2,0)," ") -> Electric Standing Desk GO Negro | H18: 1 | I18: =IFERROR(VLOOKUP(F18,Productos!$A$2:$D$258,3,0)," ") -> Standing Desk | J18: Atlantico | K18: Barranquilla | L18: =IF(O18>0,"Despachado","En alistamiento") -> Despachado | M18: Coordinadora | N18: 3008585 -84151100462 | O18: 45666 | P18: 45668 | Q18: =IF(P18>0,"Entregado","En transito") -> Entregado | R18: =IF(L18="Despachado",NETWORKDAYS.INTL(A18,O18,11,Valores!$A$2:$A$18)-1,"PTE") -> 2 | S18: =IF(Q18="Entregado",NETWORKDAYS.INTL(A18,P18,11,Valores!$A$2:$A$18)-1,"PTE") -> 4 | V18: =IF(Q18="Entregado",IF(S18<=VLOOKUP(K18,Valores!E:F,2,0),"Cumple","No cumple"),"PTE") -> Cumple | X18: 59835
A19: 45664 | B19: =TEXT(A19,"mmmm") -> enero | C19: 2382 | D19: Venta | E19: Henry De Alba | F19: TECUTRN2C | G19: =IFERROR(VLOOKUP(F19,Productos!$A$2:$D$258,2,0)," ") -> Superficie Roble Negro 120x70 Clasico Small | H19: 1 | I19: =IFERROR(VLOOKUP(F19,Productos!$A$2:$D$258,3,0)," ") -> Superficie | J19: Atlantico | K19: Barranquilla | L19: =IF(O19>0,"Despachado","En alistamiento") -> Despachado | M19: Coordinadora | N19: 3008587 -84151100464 | O19: 45666 | P19: 45668 | Q19: =IF(P19>0,"Entregado","En transito") -> Entregado | R19: =IF(L19="Despachado",NETWORKDAYS.INTL(A19,O19,11,Valores!$A$2:$A$18)-1,"PTE") -> 2 | S19: =IF(Q19="Entregado",NETWORKDAYS.INTL(A19,P19,11,Valores!$A$2:$A$18)-1,"PTE") -> 4 | V19: =IF(Q19="Entregado",IF(S19<=VLOOKUP(K19,Valores!E:F,2,0),"Cumple","No cumple"),"PTE") -> Cumple | X19: 39078
A20: 45664 | B20: =TEXT(A20,"mmmm") -> enero | C20: 2383 | D20: Venta | E20: Carlos Andres Polanco Triana | F20: TECU3FNPRO | G20: =IFERROR(VLOOKUP(F20,Productos!$A$2:$D$258,2,0)," ") -> Electric Standing Desk PRO Negro | H20: 1 | I20: =IFERROR(VLOOKUP(F20,Productos!$A$2:$D$258,3,0)," ") -> Standing Desk | J20: Huila | K20: Neiva | L20: =IF(O20>0,"Despachado","En alistamiento") -> Despachado | M20: Coordinadora | N20: 3008595 -84151100470 | O20: 45666 | P20: 45668 | Q20: =IF(P20>0,"Entregado","En transito") -> Entregado | R20: =IF(L20="Despachado",NETWORKDAYS.INTL(A20,O20,11,Valores!$A$2:$A$18)-1,"PTE") -> 2 | S20: =IF(Q20="Entregado",NETWORKDAYS.INTL(A20,P20,11,Valores!$A$2:$A$18)-1,"PTE") -> 4 | V20: =IF(Q20="Entregado",IF(S20<=VLOOKUP(K20,Valores!E:F,2,0),"Cumple","No cumple"),"PTE") -> Cumple | X20: 62467
A21: 45664 | B21: =TEXT(A21,"mmmm") -> enero | C21: 2383 | D21: Venta | E21: Carlos Andres Polanco Triana | F21: TECUTCO4C | G21: =IFERROR(VLOOKUP(F21,Productos!$A$2:$D$258,2,0)," ") -> Superficie Caramelo 140x70 Clasico | H21: 1 | I21: =IFERROR(VLOOKUP(F21,Productos!$A$2:$D$258,3,0)," ") -> Superficie | J21: Huila | K21: Neiva | L21: =IF(O21>0,"Despachado","En alistamiento") -> Despachado | M21: Coordinadora | N21: 3008596 -84151100471 | O21: 45666 | P21: 45668 | Q21: =IF(P21>0,"Entregado","En transito") -> Entregado | R21: =IF(L21="Despachado",NETWORKDAYS.INTL(A21,O21,11,Valores!$A$2:$A$18)-1,"PTE") -> 2 | S21: =IF(Q21="Entregado",NETWORKDAYS.INTL(A21,P21,11,Valores!$A$2:$A$18)-1,"PTE") -> 4 | V21: =IF(Q21="Entregado",IF(S21<=VLOOKUP(K21,Valores!E:F,2,0),"Cumple","No cumple"),"PTE") -> Cumple | X21: 39078
A22: 45665 | B22: =TEXT(A22,"mmmm") -> enero | C22: 2384 | D22: Venta | E22: Samuel Antonio Cabezas Tibaquicha | F22: TECU3FNPRO | G22: =IFERROR(VLOOKUP(F22,Productos!$A$2:$D$258,2,0)," ") -> Electric Standing Desk PRO Negro | H22: 1 | I22: =IFERROR(VLOOKUP(F22,Productos!$A$2:$D$258,3,0)," ") -> Standing Desk | J22: Bogotá y alrededores | K22: Cota | L22: =IF(O22>0,"Despachado","En alistamiento") -> Despachado | M22: Coordinadora | N22: 3006418 -84151099260 | O22: 45665 | P22: 45666 | Q22: =IF(P22>0,"Entregado","En transito") -> Entregado | R22: =IF(L22="Despachado",NETWORKDAYS.INTL(A22,O22,11,Valores!$A$2:$A$18)-1,"PTE") -> 0 | S22: =IF(Q22="Entregado",NETWORKDAYS.INTL(A22,P22,11,Valores!$A$2:$A$18)-1,"PTE") -> 1 | V22: =IF(Q22="Entregado",IF(S22<=VLOOKUP(K22,Valores!E:F,2,0),"Cumple","No cumple"),"PTE") -> Cumple | X22: 42921
A23: 45665 | B23: =TEXT(A23,"mmmm") -> enero | C23: 2384 | D23: Venta | E23: Samuel Antonio Cabezas Tibaquicha | F23: TECUDSN | G23: =IFERROR(VLOOKUP(F23,Productos!$A$2:$D$258,2,0)," ") -> Desk Stool Negra Silla ajustable | H23: 1 | I23: =IFERROR(VLOOKUP(F23,Productos!$A$2:$D$258,3,0)," ") -> Silla | J23: Bogotá y alrededores | K23: Cota | L23: =IF(O23>0,"Despachado","En alistamiento") -> Despachado | M23: Coordinadora | N23: 3006424 -84151099263 | O23: 45665 | P23: 45666 | Q23: =IF(P23>0,"Entregado","En transito") -> Entregado | R23: =IF(L23="Despachado",NETWORKDAYS.INTL(A23,O23,11,Valores!$A$2:$A$18)-1,"PTE") -> 0 | S23: =IF(Q23="Entregado",NETWORKDAYS.INTL(A23,P23,11,Valores!$A$2:$A$18)-1,"PTE") -> 1 | V23: =IF(Q23="Entregado",IF(S23<=VLOOKUP(K23,Valores!E:F,2,0),"Cumple","No cumple"),"PTE") -> Cumple | X23: 26609
A24: 45665 | B24: =TEXT(A24,"mmmm") -> enero | C24: 2385 | D24: Venta | E24: Diana Ruiz | F24: TECU3FNPRO | G24: =IFERROR(VLOOKUP(F24,Productos!$A$2:$D$258,2,0)," ") -> Electric Standing Desk PRO Negro | H24: 1 | I24: =IFERROR(VLOOKUP(F24,Productos!$A$2:$D$258,3,0)," ") -> Standing Desk | J24: Bogotá y alrededores | K24: Bogota | L24: =IF(O24>0,"Despachado","En alistamiento") -> Despachado | M24: Coordinadora | N24: 3009172 -84151100736 | O24: 45666 | P24: 45667 | Q24: =IF(P24>0,"Entregado","En transito") -> Entregado | R24: =IF(L24="Despachado",NETWORKDAYS.INTL(A24,O24,11,Valores!$A$2:$A$18)-1,"PTE") -> 1 | S24: =IF(Q24="Entregado",NETWORKDAYS.INTL(A24,P24,11,Valores!$A$2:$A$18)-1,"PTE") -> 2 | V24: =IF(Q24="Entregado",IF(S24<=VLOOKUP(K24,Valores!E:F,2,0),"Cumple","No cumple"),"PTE") -> Cumple | X24: 42921
A25: 45665 | B25: =TEXT(A25,"mmmm") -> enero | C25: 2385 | D25: Venta | E25: Diana Ruiz | F25: TECUTFE4C | G25: =IFERROR(VLOOKUP(F25,Productos!$A$2:$D$258,2,0)," ") -> Superficie Fresno Europeo 140x70 Clasico | H25: 1 | I25: =IFERROR(VLOOKUP(F25,Productos!$A$2:$D$258,3,0)," ") -> Superficie | J25: Bogotá y alrededores | K25: Bogota | L25: =IF(O25>0,"Despachado","En alistamiento") -> Despachado | M25: Coordinadora | N25: 3009173 -84151100737 | O25: 45666 | P25: 45667 | Q25: =IF(P25>0,"Entregado","En transito") -> Entregado | R25: =IF(L25="Despachado",NETWORKDAYS.INTL(A25,O25,11,Valores!$A$2:$A$18)-1,"PTE") -> 1 | S25: =IF(Q25="Entregado",NETWORKDAYS.INTL(A25,P25,11,Valores!$A$2:$A$18)-1,"PTE") -> 2 | V25: =IF(Q25="Entregado",IF(S25<=VLOOKUP(K25,Valores!E:F,2,0),"Cumple","No cumple"),"PTE") -> Cumple | X25: 24093
A26: 45665 | B26: =TEXT(A26,"mmmm") -> enero | C26: 2386 | D26: Venta | E26: Samuel Vélez Sanín | F26: TECU2FNG | G26: =IFERROR(VLOOKUP(F26,Productos!$A$2:$D$258,2,0)," ") -> Electric Standing Desk GO Negro | H26: 1 | I26: =IFERROR(VLOOKUP(F26,Productos!$A$2:$D$258,3,0)," ") -> Standing Desk | J26: Antioquia | K26: Envigado | L26: =IF(O26>0,"Despachado","En alistamiento") -> Despachado | M26: Coordinadora | N26: 3008732 -84151100542 | O26: 45666 | P26: 45667 | Q26: =IF(P26>0,"Entregado","En transito") -> Entregado | R26: =IF(L26="Despachado",NETWORKDAYS.INTL(A26,O26,11,Valores!$A$2:$A$18)-1,"PTE") -> 1 | S26: =IF(Q26="Entregado",NETWORKDAYS.INTL(A26,P26,11,Valores!$A$2:$A$18)-1,"PTE") -> 2 | V26: =IF(Q26="Entregado",IF(S26<=VLOOKUP(K26,Valores!E:F,2,0),"Cumple","No cumple"),"PTE") -> Cumple | X26: 41593
A27: 45665 | B27: =TEXT(A27,"mmmm") -> enero | C27: 2386 | D27: Venta | E27: Samuel Vélez Sanín | F27: TECUTFE2C | G27: =IFERROR(VLOOKUP(F27,Productos!$A$2:$D$258,2,0)," ") -> Superficie Fresno Europeo 120x70 Clasico Small | H27: 1 | I27: =IFERROR(VLOOKUP(F27,Productos!$A$2:$D$258,3,0)," ") -> Superficie | J27: Antioquia | K27: Envigado | L27: =IF(O27>0,"Despachado","En alistamiento") -> Despachado | M27: Coordinadora | N27: 3008734 -84151100543 | O27: 45666 | P27: 45668 | Q27: =IF(P27>0,"Entregado","En transito") -> Entregado | R27: =IF(L27="Despachado",NETWORKDAYS.INTL(A27,O27,11,Valores!$A$2:$A$18)-1,"PTE") -> 1 | S27: =IF(Q27="Entregado",NETWORKDAYS.INTL(A27,P27,11,Valores!$A$2:$A$18)-1,"PTE") -> 3 | V27: =IF(Q27="Entregado",IF(S27<=VLOOKUP(K27,Valores!E:F,2,0),"Cumple","No cumple"),"PTE") -> Cumple | X27: 24093
A28: 45665 | B28: =TEXT(A28,"mmmm") -> enero | C28: 2387 | D28: Venta | E28: Miguel Saavedra | F28: TECUACO | G28: =IFERROR(VLOOKUP(F28,Productos!$A$2:$D$258,2,0)," ") -> Archivador TECU Caramelo | H28: 1 | I28: =IFERROR(VLOOKUP(F28,Productos!$A$2:$D$258,3,0)," ") -> Archivador | J28: Bogotá y alrededores | K28: Bogota | L28: =IF(O28>0,"Despachado","En alistamiento") -> Despachado | M28: Envia | N28: 3006909 -954101121278 | O28: 45665 | P28: 45666 | Q28: =IF(P28>0,"Entregado","En transito") -> Entregado | R28: =IF(L28="Despachado",NETWORKDAYS.INTL(A28,O28,11,Valores!$A$2:$A$18)-1,"PTE") -> 0 | S28: =IF(Q28="Entregado",NETWORKDAYS.INTL(A28,P28,11,Valores!$A$2:$A$18)-1,"PTE") -> 1 | V28: =IF(Q28="Entregado",IF(S28<=VLOOKUP(K28,Valores!E:F,2,0),"Cumple","No cumple"),"PTE") -> Cumple | X28: 70717
A29: 45666 | B29: =TEXT(A29,"mmmm") -> enero | C29: 2388 | D29: Venta | E29: CAROLINA RAMIREZ RESTREPO | F29: TECU2FNG | G29: =IFERROR(VLOOKUP(F29,Productos!$A$2:$D$258,2,0)," ") -> Electric Standing Desk GO Negro | H29: 1 | I29: =IFERROR(VLOOKUP(F29,Productos!$A$2:$D$258,3,0)," ") -> Standing Desk | J29: Antioquia | K29: Carmen de Viboral | L29: =IF(O29>0,"Despachado","En alistamiento") -> Despachado | M29: Coordinadora | N29: 3008988 -84151100690 | O29: 45666 | P29: 45681 | Q29: =IF(P29>0,"Entregado","En transito") -> Entregado | R29: =IF(L29="Despachado",NETWORKDAYS.INTL(A29,O29,11,Valores!$A$2:$A$18)-1,"PTE") -> 0 | S29: =IF(Q29="Entregado",NETWORKDAYS.INTL(A29,P29,11,Valores!$A$2:$A$18)-1,"PTE") -> 13 | V29: =IF(Q29="Entregado",IF(S29<=VLOOKUP(K29,Valores!E:F,2,0),"Cumple","No cumple"),"PTE") -> No cumple | X29: 112444 | AA29: Novedad - Se envia a oto pueblo por error en Shopify generar guias // se solicita devolucion a la bodega
A30: 45666 | B30: =TEXT(A30,"mmmm") -> enero | C30: 2388 | D30: Venta | E30: CAROLINA RAMIREZ RESTREPO | F30: TECUTCO6C | G30: =IFERROR(VLOOKUP(F30,Productos!$A$2:$D$258,2,0)," ") -> Superficie Caramelo 160x70 Clasico | H30: 1 | I30: =IFERROR(VLOOKUP(F30,Productos!$A$2:$D$258,3,0)," ") -> Superficie | J30: Antioquia | K30: Carmen de Viboral | L30: =IF(O30>0,"Despachado","En alistamiento") -> Despachado | M30: Coordinadora | N30: 3008990 -84151100691 | O30: 45666 | P30: 45681 | Q30: =IF(P30>0,"Entregado","En transito") -> Entregado | R30: =IF(L30="Despachado",NETWORKDAYS.INTL(A30,O30,11,Valores!$A$2:$A$18)-1,"PTE") -> 0 | S30: =IF(Q30="Entregado",NETWORKDAYS.INTL(A30,P30,11,Valores!$A$2:$A$18)-1,"PTE") -> 13 | V30: =IF(Q30="Entregado",IF(S30<=VLOOKUP(K30,Valores!E:F,2,0),"Cumple","No cumple"),"PTE") -> No cumple | X30: 98264 | AA30: Novedad - Se envia a oto pueblo por error en Shopify generar guias // se solicita devolucion a la bodega
A31: 45666 | B31: =TEXT(A31,"mmmm") -> enero | C31: 2389 | D31: Venta | E31: Alexander Gomez Chaparro | F31: TECULFN2 | G31: =IFERROR(VLOOKUP(F31,Productos!$A$2:$D$258,2,0)," ") -> Electric Standing Desk En L Frame Negro 2.0 | H31: 1 | I31: =IFERROR(VLOOKUP(F31,Productos!$A$2:$D$258,3,0)," ") -> Standing Desk | J31: Boyaca | K31: Tunja | L31: =IF(O31>0,"Despachado","En alistamiento") -> Despachado | M31: Coordinadora | N31: 3011856 -84151101651 | O31: 45667 | P31: 45670 | Q31: =IF(P31>0,"Entregado","En transito") -> Entregado | R31: =IF(L31="Despachado",NETWORKDAYS.INTL(A31,O31,11,Valores!$A$2:$A$18)-1,"PTE") -> 1 | S31: =IF(Q31="Entregado",NETWORKDAYS.INTL(A31,P31,11,Valores!$A$2:$A$18)-1,"PTE") -> 3 | V31: =IF(Q31="Entregado",IF(S31<=VLOOKUP(K31,Valores!E:F,2,0),"Cumple","No cumple"),"PTE") -> Cumple | X31: 96409
A32: 45666 | B32: =TEXT(A32,"mmmm") -> enero | C32: 2389 | D32: Venta | E32: Alexander Gomez Chaparro | F32: TECUTLNS | G32: =IFERROR(VLOOKUP(F32,Productos!$A$2:$D$258,2,0)," ") -> Superficie en L Negro 180x150cm x 70 | H32: 1 | I32: =IFERROR(VLOOKUP(F32,Productos!$A$2:$D$258,3,0)," ") -> Superficie | J32: Boyaca | K32: Tunja | L32: =IF(O32>0,"Despachado","En alistamiento") -> Despachado | M32: Coordinadora | N32: 3011858 -84151101652 | O32: 45667 | P32: 45670 | Q32: =IF(P32>0,"Entregado","En transito") -> Entregado | R32: =IF(L32="Despachado",NETWORKDAYS.INTL(A32,O32,11,Valores!$A$2:$A$18)-1,"PTE") -> 1 | S32: =IF(Q32="Entregado",NETWORKDAYS.INTL(A32,P32,11,Valores!$A$2:$A$18)-1,"PTE") -> 3 | V32: =IF(Q32="Entregado",IF(S32<=VLOOKUP(K32,Valores!E:F,2,0),"Cumple","No cumple"),"PTE") -> Cumple | X32: 44340
A33: 45666 | B33: =TEXT(A33,"mmmm") -> enero | C33: 2390 | D33: Venta | E33: Alexander Gomez Chaparro | F33: TECUCT | G33: =IFERROR(VLOOKUP(F33,Productos!$A$2:$D$258,2,0)," ") -> Bandeja de cables | H33: 1 | I33: =IFERROR(VLOOKUP(F33,Productos!$A$2:$D$258,3,0)," ") -> Accesorio | J33: Boyaca | K33: Tunja | L33: =IF(O33>0,"Despachado","En alistamiento") -> Despachado | M33: Coordinadora | N33: 3011897 -84151101678 | O33: 45667 | P33: 45670 | Q33: =IF(P33>0,"Entregado","En transito") -> Entregado | R33: =IF(L33="Despachado",NETWORKDAYS.INTL(A33,O33,11,Valores!$A$2:$A$18)-1,"PTE") -> 1 | S33: =IF(Q33="Entregado",NETWORKDAYS.INTL(A33,P33,11,Valores!$A$2:$A$18)-1,"PTE") -> 3 | V33: =IF(Q33="Entregado",IF(S33<=VLOOKUP(K33,Valores!E:F,2,0),"Cumple","No cumple"),"PTE") -> Cumple
A34: 45666 | B34: =TEXT(A34,"mmmm") -> enero | C34: 2390 | D34: Venta | E34: Alexander Gomez Chaparro | F34: TECUBDPA | G34: =IFERROR(VLOOKUP(F34,Productos!$A$2:$D$258,2,0)," ") -> Desk Pad B Negro Azul | H34: 1 | I34: =IFERROR(VLOOKUP(F34,Productos!$A$2:$D$258,3,0)," ") -> Accesorio | J34: Boyaca | K34: Tunja | L34: =IF(O34>0,"Despachado","En alistamiento") -> Despachado | M34: Coordinadora | N34: 3011889 -84151101671 | O34: 45667 | P34: 45670 | Q34: =IF(P34>0,"Entregado","En transito") -> Entregado | R34: =IF(L34="Despachado",NETWORKDAYS.INTL(A34,O34,11,Valores!$A$2:$A$18)-1,"PTE") -> 1 | S34: =IF(Q34="Entregado",NETWORKDAYS.INTL(A34,P34,11,Valores!$A$2:$A$18)-1,"PTE") -> 3 | V34: =IF(Q34="Entregado",IF(S34<=VLOOKUP(K34,Valores!E:F,2,0),"Cumple","No cumple"),"PTE") -> Cumple | X34: 16617
A35: 45666 | B35: =TEXT(A35,"mmmm") -> enero | C35: 2390 | D35: Venta | E35: Alexander Gomez Chaparro | F35: TECUDSN | G35: =IFERROR(VLOOKUP(F35,Productos!$A$2:$D$258,2,0)," ") -> Desk Stool Negra Silla ajustable | H35: 1 | I35: =IFERROR(VLOOKUP(F35,Productos!$A$2:$D$258,3,0)," ") -> Silla | J35: Boyaca | K35: Tunja | L35: =IF(O35>0,"Despachado","En alistamiento") -> Despachado | M35: Coordinadora | N35: 3011879 -84151101661 | O35: 45667 | P35: 45670 | Q35: =IF(P35>0,"Entregado","En transito") -> Entregado | R35: =IF(L35="Despachado",NETWORKDAYS.INTL(A35,O35,11,Valores!$A$2:$A$18)-1,"PTE") -> 1 | S35: =IF(Q35="Entregado",NETWORKDAYS.INTL(A35,P35,11,Valores!$A$2:$A$18)-1,"PTE") -> 3 | V35: =IF(Q35="Entregado",IF(S35<=VLOOKUP(K35,Valores!E:F,2,0),"Cumple","No cumple"),"PTE") -> Cumple | X35: 40942
A36: 45666 | B36: =TEXT(A36,"mmmm") -> enero | C36: 2390 | D36: Venta | E36: Alexander Gomez Chaparro | F36: TECURN | G36: =IFERROR(VLOOKUP(F36,Productos!$A$2:$D$258,2,0)," ") -> Repisa Negro | H36: 1 | I36: =IFERROR(VLOOKUP(F36,Productos!$A$2:$D$258,3,0)," ") -> Repisa | J36: Boyaca | K36: Tunja | L36: =IF(O36>0,"Despachado","En alistamiento") -> Despachado | M36: Coordinadora | N36: NA | O36: 45667 | P36: 45670 | Q36: =IF(P36>0,"Entregado","En transito") -> Entregado | R36: =IF(L36="Despachado",NETWORKDAYS.INTL(A36,O36,11,Valores!$A$2:$A$18)-1,"PTE") -> 1 | S36: =IF(Q36="Entregado",NETWORKDAYS.INTL(A36,P36,11,Valores!$A$2:$A$18)-1,"PTE") -> 3 | V36: =IF(Q36="Entregado",IF(S36<=VLOOKUP(K36,Valores!E:F,2,0),"Cumple","No cumple"),"PTE") -> Cumple
A37: 45666 | B37: =TEXT(A37,"mmmm") -> enero | C37: 2391 | D37: Venta | E37: Alexander Gomez Chaparro | F37: TECUCT | G37: =IFERROR(VLOOKUP(F37,Productos!$A$2:$D$258,2,0)," ") -> Bandeja de cables | H37: 1 | I37: =IFERROR(VLOOKUP(F37,Productos!$A$2:$D$258,3,0)," ") -> Accesorio | J37: Boyaca | K37: Tunja | L37: =IF(O37>0,"Despachado","En alistamiento") -> Despachado | M37: Coordinadora | N37: 3011897 -84151101678 | O37: 45667 | P37: 45670 | Q37: =IF(P37>0,"Entregado","En transito") -> Entregado | R37: =IF(L37="Despachado",NETWORKDAYS.INTL(A37,O37,11,Valores!$A$2:$A$18)-1,"PTE") -> 1 | S37: =IF(Q37="Entregado",NETWORKDAYS.INTL(A37,P37,11,Valores!$A$2:$A$18)-1,"PTE") -> 3 | V37: =IF(Q37="Entregado",IF(S37<=VLOOKUP(K37,Valores!E:F,2,0),"Cumple","No cumple"),"PTE") -> Cumple | X37: 24885
A38: 45667 | B38: =TEXT(A38,"mmmm") -> enero | C38: 2392 | D38: Venta | E38: David Cadavid | F38: TECU3FNPRO | G38: =IFERROR(VLOOKUP(F38,Productos!$A$2:$D$258,2,0)," ") -> Electric Standing Desk PRO Negro | H38: 1 | I38: =IFERROR(VLOOKUP(F38,Productos!$A$2:$D$258,3,0)," ") -> Standing Desk | J38: Antioquia | K38: Envigado | L38: =IF(O38>0,"Despachado","En alistamiento") -> Despachado | M38: Coordinadora | N38: 3015845 -84151103419 | O38: 45670.7 | P38: 45671.644 | Q38: =IF(P38>0,"Entregado","En transito") -> Entregado | R38: =IF(L38="Despachado",NETWORKDAYS.INTL(A38,O38,11,Valores!$A$2:$A$18)-1,"PTE") -> 2 | S38: =IF(Q38="Entregado",NETWORKDAYS.INTL(A38,P38,11,Valores!$A$2:$A$18)-1,"PTE") -> 3 | V38: =IF(Q38="Entregado",IF(S38<=VLOOKUP(K38,Valores!E:F,2,0),"Cumple","No cumple"),"PTE") -> Cumple | X38: =VLOOKUP(N38,[1]Hoja1!$G:$BE,39,0) -> 42921
A39: 45667 | B39: =TEXT(A39,"mmmm") -> enero | C39: 2392 | D39: Venta | E39: David Cadavid | F39: TECUTCO8C | G39: =IFERROR(VLOOKUP(F39,Productos!$A$2:$D$258,2,0)," ") -> Superficie Caramelo 180x70 Clasico | H39: 1 | I39: =IFERROR(VLOOKUP(F39,Productos!$A$2:$D$258,3,0)," ") -> Superficie | J39: Antioquia | K39: Envigado | L39: =IF(O39>0,"Despachado","En alistamiento") -> Despachado | M39: Coordinadora | N39: 3015847 -84151103420 | O39: 45670.7 | P39: 45671.644 | Q39: =IF(P39>0,"Entregado","En transito") -> Entregado | R39: =IF(L39="Despachado",NETWORKDAYS.INTL(A39,O39,11,Valores!$A$2:$A$18)-1,"PTE") -> 2 | S39: =IF(Q39="Entregado",NETWORKDAYS.INTL(A39,P39,11,Valores!$A$2:$A$18)-1,"PTE") -> 3 | V39: =IF(Q39="Entregado",IF(S39<=VLOOKUP(K39,Valores!E:F,2,0),"Cumple","No cumple"),"PTE") -> Cumple | X39: =VLOOKUP(N39,[1]Hoja1!$G:$BE,39,0) -> 26749
A40: 45667 | B40: =TEXT(A40,"mmmm") -> enero | C40: 2392 | D40: Venta | E40: David Cadavid | F40: TECUCT | G40: =IFERROR(VLOOKUP(F40,Productos!$A$2:$D$258,2,0)," ") -> Bandeja de cables | H40: 1 | I40: =IFERROR(VLOOKUP(F40,Productos!$A$2:$D$258,3,0)," ") -> Accesorio | J40: Antioquia | K40: Envigado | L40: =IF(O40>0,"Despachado","En alistamiento") -> Despachado | M40: Coordinadora | N40: 3015858 -84151103425 | O40: 45670.7 | P40: 45671.644 | Q40: =IF(P40>0,"Entregado","En transito") -> Entregado | R40: =IF(L40="Despachado",NETWORKDAYS.INTL(A40,O40,11,Valores!$A$2:$A$18)-1,"PTE") -> 2 | S40: =IF(Q40="Entregado",NETWORKDAYS.INTL(A40,P40,11,Valores!$A$2:$A$18)-1,"PTE") -> 3 | V40: =IF(Q40="Entregado",IF(S40<=VLOOKUP(K40,Valores!E:F,2,0),"Cumple","No cumple"),"PTE") -> Cumple | X40: =VLOOKUP(N40,[1]Hoja1!$G:$BE,39,0) -> 24885
A41: 45668 | B41: =TEXT(A41,"mmmm") -> enero | C41: 2393 | D41: Venta | E41: Santiago Garzon Diaz | F41: TECU2FNG | G41: =IFERROR(VLOOKUP(F41,Productos!$A$2:$D$258,2,0)," ") -> Electric Standing Desk GO Negro | H41: 1 | I41: =IFERROR(VLOOKUP(F41,Productos!$A$2:$D$258,3,0)," ") -> Standing Desk | J41: Antioquia | K41: Medellin | L41: =IF(O41>0,"Despachado","En alistamiento") -> Despachado | M41: Coordinadora | N41: 3015877 -84151103435 | O41: 45670.7 | P41: 45671.411 | Q41: =IF(P41>0,"Entregado","En transito") -> Entregado | R41: =IF(L41="Despachado",NETWORKDAYS.INTL(A41,O41,11,Valores!$A$2:$A$18)-1,"PTE") -> 1 | S41: =IF(Q41="Entregado",NETWORKDAYS.INTL(A41,P41,11,Valores!$A$2:$A$18)-1,"PTE") -> 2 | V41: =IF(Q41="Entregado",IF(S41<=VLOOKUP(K41,Valores!E:F,2,0),"Cumple","No cumple"),"PTE") -> Cumple | X41: =VLOOKUP(N41,[1]Hoja1!$G:$BE,39,0) -> 41593
A42: 45668 | B42: =TEXT(A42,"mmmm") -> enero | C42: 2393 | D42: Venta | E42: Santiago Garzon Diaz | G42: Servicio de instalacion | H42: 1 | I42: Instalacion | J42: Antioquia | K42: Medellin | L42: Instalacion | M42: NA | N42: NA | O42: NA | P42: NA | Q42: =IF(P42>0,"Entregado","En transito") -> Entregado | R42: =IF(L42="Despachado",NETWORKDAYS.INTL(A42,O42,11,Valores!$A$2:$A$18)-1,"PTE") -> PTE | S42: =IF(Q42="Entregado",NETWORKDAYS.INTL(A42,P42,11,Valores!$A$2:$A$18)-1,"PTE") -> #VALUE! | V42: =IF(Q42="Entregado",IF(S42<=VLOOKUP(K42,Valores!E:F,2,0),"Cumple","No cumple"),"PTE") -> #VALUE! | X42: 0
...

Sheet Productos
A1: PRODUCTOS
A2: CODIGO | B2: PRODUCTO | C2: Categoria | D2: Valores Fletes
A3: TECUTRM8M | B3: Superficie Roble Miel 180x70 Moderno | C3: Superficie | D3: 35000
A4: TECUTRM8C | B4: Superficie Roble Miel 180x70 Clasico | C4: Superficie | D4: 35000
A5: TECUTRM5C | B5: Superficie Roble Miel 150x70 Clasico | C5: Superficie | D5: 35000
A6: TECUTRC8C | B6: Superficie Roble Caramelo 180x70 Clasico | C6: Superficie | D6: 35000
A7: TECUTRC5C | B7: Superficie Roble Caramelo 150x70 Clasico | C7: Superficie | D7: 35000
A8: TECUTNE | B8: Superficie orden especial Color: Wengue | C8: Superficie | D8: 35000
A9: TECUTBE | B9: Superficie orden especial Color: Niebla | C9: Superficie | D9: 35000
A10: TECUTCCE | B10: Superficie orden especial Color: Miel | C10: Superficie | D10: 35000
A11: TECUTCOE | B11: Superficie orden especial Color: Caramelo | C11: Superficie | D11: 35000
A12: TECUTB20C | B12: Superficie Niebla 200x70 Clasico | C12: Superficie | D12: 35000
A13: TECUTB9C | B13: Superficie Niebla 190x70 Clasico | C13: Superficie | D13: 35000
A14: TECUTB8M | B14: Superficie Niebla 180x70 Moderno | C14: Superficie | D14: 35000
... A173: TECURCC | B173: Repisa Miel | C173: Repisa | D173: 25000
A174: TECURFB-80 | B174: Repisa Flotante Niebla x 80cm | C174: Repisa
A175: TECURFB-70 | B175: Repisa Flotante Niebla x 70cm | C175: Repisa
A176: TECURFB-60 | B176: Repisa Flotante Niebla x 60cm | C176: Repisa
A177: TECURFN-80 | B177: Repisa Flotante Negro x 80cm | C177: Repisa
A178: TECURFN-70 | B178: Repisa Flotante Negro x 70cm | C178: Repisa
A179: TECURFN-60 | B179: Repisa Flotante Negro x 60cm | C179: Repisa
A180: TECURFFE -80 | B180: Repisa Flotante Fresno Europeo x 80cm | C180: Repisa
A181: TECURFFE -70 | B181: Repisa Flotante Fresno Europeo x 70cm | C181: Repisa
A182: TECURFFE -60 | B182: Repisa Flotante Fresno Europeo x 60cm | C182: Repisa
A183: TECURFCO-80 | B183: Repisa Flotante Caramelo x 80cm | C183: Repisa
A184: TECURFCO-70 | B184: Repisa Flotante Caramelo x 70cm | C184: Repisa
A185: TECURFCO-60 | B185: Repisa Flotante Caramelo x 60cm | C185: Repisa
... A197: TECURECO-110 | B197: Repisa Escritorio Caramelo x 110cm | C197: Repisa
A198: TECURCO | B198: Repisa Caramelo | C198: Repisa | D198: 25000
A199: TECUBLS | B199: Laptop Stand B | C199: Accesorio | D199: 50000
A200: TECUFX-T76 | B200: Escritorio FIjo Linea - T x 76,5 cm | C200: Escritorio Fijo
A201: TECUFX-T72 | B201: Escritorio FIjo Linea - T x 72,5 cm | C201: Escritorio Fijo
A202: TECUFX-T68 | B202: Escritorio FIjo Linea - T x 68,5 cm | C202: Escritorio Fijo
A203: TECUFX-T64 | B203: Escritorio FIjo Linea - T x 64,5 cm | C203: Escritorio Fijo
A204: TECU2FNG | B204: Electric Standing Desk GO Negro | C204: Standing Desk | D204: 40000
A205: TECU2FGGO | B205: Electric Standing Desk GO Gris | C205: Standing Desk | D205: 40000
A206: TECU2FBGO | B206: Electric Standing Desk GO Blanco | C206: Standing Desk | D206: 40000
A207: TECULFG | B207: Electric Standing Desk En L Frame Gris | C207: Standing Desk | D207: 40000
A208: TECU3FNCRO | B208: Electric Standing Desk PRO Negro circular | C208: Standing Desk | D208: 40000
A209: TECU3FNPRO | B209: Electric Standing Desk PRO Negro | C209: Standing Desk | D209: 40000
...

Sheet Indicadores Despachos
A1: INDICADORES OPERACIÓN LOGISTICA TECU
A5: 1. TIEMPOS DE DESPACHO Y DE ENTREGAS
A7: Mes | B7: mayo | L7: Mes | M7: mayo
A8: Status Despacho | B8: Despachado | L8: Status entrega | M8: Entregado
A10: Promedio de Tiempo de despacho de orden | B10: Categoria | L10: Promedio de Tiempo de entrega de la orden | M10: Categoria
A11: Ciudad | B11: Standing Desk | C11: Superficie | D11: Accesorio | E11: Archivador | F11: Repisa | G11: Silla | H11: Ruedas | L11: Ciudad | M11: Standing Desk | N11: Superficie | O11: Accesorio | P11: Archivador | Q11: Repisa | R11: Silla | S11: Ruedas
A12: Bogotá y alrededores | B12: 0.625 | C12: 0.6 | D12: 1 | E12: 2.6666667 | F12: 0 | G12: 0 | H12: 0 | L12: Bogotá y alrededores | M12: 2 | N12: 2.5333333 | O12: 2.4285714 | P12: 4 | Q12: 2 | R12: 1 | S12: 1
A13: Antioquia | B13: 0.5 | C13: 0.66666667 | D13: 1 | H13: 0 | L13: Antioquia | M13: 1.5 | N13: 1.6666667 | O13: 2 | S13: 1
A14: Valle del Cauca | B14: 0 | C14: 0 | L14: Valle del Cauca | M14: 1 | N14: 1
A15: Atlantico | D15: 0 | G15: 0 | L15: Atlantico | O15: 2 | R15: 2
A16: Santander | B16: 0 | C16: 0 | L16: Santander | M16: 2 | N16: 2
A17: Caldas | B17: 1 | C17: 1 | L17: Caldas | M17: 10 | N17: 11
A28: 2. TIEMPOS DE DESPACHO Y DE ENTREGAS POR CIUDAD
A31: Mes | B31: mayo
A32: Status entrega | B32: Entregado
A34: Promedio de Tiempo de entrega de la orden | B34: Categoria
A35: Ciudad | B35: Standing Desk | C35: Superficie | D35: Accesorio | E35: Archivador | F35: Repisa | G35: Silla | H35: Ruedas | I35: Instalacion
A36: Bogotá y alrededores | B36: 2 | C36: 2.5333333 | D36: 2.4285714 | E36: 4 | F36: 2 | G36: 1 | H36: 1 | I36: #VALUE!
A37: Antioquia | B37: 1.5 | C37: 1.6666667 | D37: 2 | H37: 1 | I37: #VALUE!
A38: Valle del Cauca | B38: 1 | C38: 1
A39: Atlantico | D39: 2 | G39: 2
A40: Santander | B40: 2 | C40: 2
A41: Caldas | B41: 10 | C41: 11

Sheet OKR
A1: Indicador OTIF | E1: =D2*E31 -> 961.97778
A2: 1 a 3 días Ciudades principales 1 a 5 días Ciudades Secundarias | D2: =B13/(B13+C13) -> 0.81111111 | E2: NNS
A4: Concepto | B4: Venta
A5: Status entrega | B5: Entregado
A7: Cuenta de No orden | B7: Cumple NNS
A8: Mes | B8: Cumple | C8: No cumple | D8: (en blanco) | E8: #N/D | F8: #¡VALOR! | G8: Total general
A9: enero | B9: 70 | C9: 25 | G9: 95
A10: febrero | B10: 86 | C10: 5 | G10: 91
A11: marzo | B11: 60 | C11: 5 | G11: 65
A12: abril | B12: 111 | C12: 24 | E12: 3 | G12: 138
A13: mayo | B13: 73 | C13: 17 | E13: 12 | G13: 102
A14: junio | B14: 80 | C14: 8 | E14: 5 | G14: 93
A15: julio | B15: 80 | C15: 16 | E15: 9 | G15: 105
A16: agosto | B16: 44 | C16: 19 | E16: 6 | G16: 69
A17: septiembre | B17: 50 | C17: 12 | E17: 3 | F17: 2 | G17: 67
A18: octubre | B18: 76 | C18: 12 | E18: 12 | F18: 1 | G18: 101
A19: noviembre | B19: 115 | C19: 31 | E19: 12 | G19: 158
A20: diciembre | B20: 49 | C20: 30 | D20: 1 | E20: 3 | G20: 83
A21: Total general | B21: 894 | C21: 204 | D21: 1 | E21: 65 | F21: 3 | G21: 1167
A31: Garantias | E31: =B37/$B$38 -> 1186
A32: Mes | B32: (Todas)
A34: Cuenta de No orden
A35: Concepto | B35: Total
A36: Garantia | B36: 13
A37: Venta | B37: 1186
A38: RIFA | B38: 1
A39: Préstamo | B39: 4
A40: Cortesia | B40: 4
A41: Cambio | B41: 1
A42: Politica Satisfaccion | B42: 1
A43: Total general | B43: 1210
C47: Stock minimo
A48: Descripcion del producto | B48: Promedio mes | C48: n+4 | D48: Inventario actual | E48: COSTO | F48: FI | G48: TRM | H48: Costo
A49: Electric Standing Desk GO Negro | B49: 17 | C49: =B49*4 -> 68 | D49: 79 | E49: 122 | F49: 1.46 | G49: 4444.36 | H49: =((E49*F49)*G49)*D49 -> 62538723
A50: Electric Standing Desk GO Gris | B50: 2 | C50: =B50*4 -> 8 | D50: 0 | E50: 122 | F50: 1.46 | G50: 4444.36 | H50: =((E50*F50)*G50)*D50 -> 0
A51: Electric Standing Desk GO Blanco | B51: 4 | C51: =B51*4 -> 16 | D51: 21 | E51: 122 | F51: 1.46 | G51: 4444.36 | H51: =((E51*F51)*G51)*D51 -> 16624217
A52: Electric Standing Desk PRO Negro | B52: 15 | C52: 60 | D52: 58 | E52: 125 | F52: 1.46 | G52: 4444.36 | H52: =((E52*F52)*G52)*D52 -> 47043551
A53: Electric Standing Desk PRO Negro circular | B53: 15 | C53: 60 | D53: 15 | E53: 125 | F53: 1.46 | G53: 4444.36 | H53: =((E53*F53)*G53)*D53 -> 12166436
A54: Electric Standing Desk PRO Gris | B54: 3.3333333 | C54: 13 | D54: 0 | E54: 125 | F54: 1.46 | G54: 4444.36 | H54: =((E54*F54)*G54)*D54 -> 0
A55: Electric Standing Desk PROBlanco | B55: 4 | C55: =B55*4 -> 16 | D55: 17 | E55: 125 | F55: 1.46 | G55: 4444.36 | H55: =((E55*F55)*G55)*D55 -> 13788627
...

Sheet Analisis Ventas
A1: INDICADORES VENTAS TECU.CO
A4: 1. RESUMEN DE VENTAS
A5: Concepto | B5: (Todas)
A7: Suma de Cantidad | B7: Categoria
A8: Mes | B8: Standing Desk | C8: Superficie | D8: Accesorio | E8: Archivador | F8: Repisa | G8: Silla | H8: Ruedas | I8: Instalacion | J8: Escritorio Fijo | L8: Total general
A9: enero | B9: 41 | C9: 38 | D9: 20 | E9: 2 | F9: 3 | G9: 3 | H9: 4 | I9: 10 | L9: 121
A10: febrero | B10: 22 | C10: 21 | D10: 10 | E10: 7 | F10: 1 | H10: 4 | I10: 2 | L10: 67
A11: marzo | B11: 36 | C11: 38 | D11: 7 | E11: 3 | F11: 4 | H11: 4 | I11: 7 | L11: 99
A12: abril | B12: 36 | C12: 34 | D12: 17 | E12: 3 | F12: 3 | G12: 5 | H12: 3 | I12: 7 | L12: 108
A13: mayo | B13: 26 | C13: 24 | D13: 12 | E13: 4 | F13: 1 | G13: 4 | H13: 4 | I13: 6 | L13: 81
A14: junio | B14: 31 | C14: 30 | D14: 22 | E14: 10 | F14: 9 | G14: 4 | H14: 3 | I14: 6 | L14: 115
A15: julio | B15: 39 | C15: 37 | D15: 19 | E15: 3 | F15: 3 | H15: 2 | I15: 6 | L15: 109
A16: agosto | B16: 29 | C16: 30 | D16: 12 | E16: 3 | F16: 3 | H16: 1 | I16: 6 | L16: 84
A17: septiembre | B17: 24 | C17: 23 | D17: 9 | E17: 5 | G17: 1 | H17: 1 | I17: 5 | L17: 68
A18: octubre | B18: 21 | C18: 24 | D18: 8 | E18: 5 | F18: 7 | G18: 3 | I18: 6 | J18: 1 | K18: 1 | L18: 76
A19: noviembre | B19: 39 | C19: 37 | D19: 10 | E19: 4 | F19: 7 | G19: 5 | I19: 3 | J19: 1 | L19: 106
A20: Total general | B20: 344 | C20: 336 | D20: 146 | E20: 49 | F20: 41 | G20: 25 | H20: 26 | I20: 64 | J20: 2 | K20: 1 | L20: 1034
A25: Mes | B25: mayo
A26: Concepto | B26: Venta
A28: Suma de Cantidad | B28: Categoria
A29: Ciudad | B29: Standing Desk | C29: Superficie | D29: Repisa | E29: Accesorio | F29: Archivador | G29: Silla | H29: Ruedas | I29: Instalacion | J29: Total general
A30: Bogotá y alrededores | B30: 16 | C30: 16 | D30: 1 | E30: 10 | F30: 4 | G30: 2 | H30: 2 | I30: 4 | J30: 55
A31: Antioquia | B31: 4 | C31: 3 | E31: 1 | H31: 2 | I31: 2 | J31: 12
A32: Valle del Cauca | B32: 3 | C32: 3 | J32: 6
A33: Atlantico | E33: 1 | G33: 2 | J33: 3
A34: Caldas | B34: 1 | C34: 1 | J34: 2
A35: Santander | B35: 1 | C35: 1 | J35: 2
A36: Total general | B36: 25 | C36: 24 | D36: 1 | E36: 12 | F36: 4 | G36: 4 | H36: 4 | I36: 6 | J36: 80
A78: Mes | B78: mayo
A79: Concepto | B79: Venta
A81: Suma de Cantidad | B81: Categoria
A82: Lugar de entrega | B82: Standing Desk | C82: Superficie | D82: Repisa | E82: Accesorio | F82: Archivador | G82: Silla | H82: Ruedas | I82: Instalacion | J82: Total general
A83: Bogota | B83: 13 | C83: 13 | E83: 8 | F83: 3 | G83: 2 | H83: 2 | I83: 4 | J83: 45
A84: Medellin | B84: 2 | C84: 1 | E84: 1 | I84: 2 | J84: 6
A85: Chia | B85: 1 | C85: 1 | E85: 1 | F85: 1 | J85: 4
A86: Cali | B86: 2 | C86: 2 | J86: 4
A87: Barranquilla | E87: 1 | G87: 2 | J87: 3
A88: Funza | B88: 1 | C88: 1 | J88: 2
A89: Retiro | B89: 1 | C89: 1 | J89: 2
A90: Soacha | B90: 1 | C90: 1 | J90: 2
...

Sheet Valores
A1: dias Festivos | D1: Ciudad entrega | E1: Lugar entrega | F1: Tiempo entrega
A2: 45658 | D2: Acacias | E2: Meta | F2: 5
A3: 45663 | D3: Aguachica | E3: Aguachica | F3: 5
A4: 45740 | D4: Antioquia | E4: Envigado | F4: 3
A5: 45764 | D5: Antioquia | E5: Medellin | F5: 3
A6: 45765 | D6: Antioquia | E6: Bello | F6: 3
A7: 45778 | D7: Antioquia | E7: Sabaneta | F7: 3
A8: 45810 | D8: Antioquia | E8: La estrella | F8: 3
A9: 45831 | D9: Antioquia | E9: El retiro | F9: 5
A10: 45838 | D10: Antioquia | E10: Caldas | F10: 5
A11: 45858 | D11: Antioquia | E11: La ceja | F11: 5
A12: 45876 | D12: Antioquia | E12: Itagui | F12: 3
A13: 45887 | D13: Antioquia | E13: Rionegro | F13: 3
... A18: 46016 | D18: Antioquia | E18: Marinilla | F18: 5
D19: Quindio | E19: Armenia | F19: 3
D20: Atlantico | E20: Soledad | F20: 5
D21: Atlantico | E21: Barranquilla | F21: 5
D22: Bogotá y alrededores | E22: Bogota | F22: 3
D23: Bogotá y alrededores | E23: Cajica | F23: 5
D24: Bogotá y alrededores | E24: Bojaca | F24: 5
D25: Bogotá y alrededores | E25: Zipaquira | F25: 5
D26: Bogotá y alrededores | E26: Choachi | F26: 5
D27: Bogotá y alrededores | E27: Chia | F27: 5
D28: Bogotá y alrededores | E28: Fusagasuga | F28: 5
D29: Bogotá y alrededores | E29: Mosquera | F29: 5
D30: Bogotá y alrededores | E30: Tocancipa | F30: 5
... D62: Cordoba | E62: Monteria | F62: 5
